Workbook

Sheet Резюме
B2: Резюме проекта
B4: Суть проекта:
B5: Проектом предусматривается создание, внедрение и ввод в промышленную эксплуатацию нейросетевого программного модуля, встраиваемого в корпоративную HRM-систему МКПАО «Яндекс». Назначение модуля – автоматизированный анализ компетенций сотрудников, выявление дефицита навыков, прогнозирование вероятных карьерных переходов и формирование персонализированных рекомендаций по обучению и развитию.
B6: Инициатор проекта:
B7: Цель проекта:
B8: Создание нейросетевого модуля для повышения эффективности управления кадрами компании "Яндекс"
B10: Основные характеристики проекта
B11: Наименование | C11: Значение
B12: Суть проекта | C12: Создание нейросетевого модуля в корпоративную HRM-систему "Яндекса", содержащего
B13: Срок реализации проекта | C13: 10 лет, 1 год разработка, 9 лет - реализация
B14: Количество работников | C14: 18 человек
B15: Количество сотрудников "Яндекс" | C15: 29000
B16: Обучение ориентировано на (численность обучающихся), чел. | C16: 5200
B17: Цель проекта | C17: Создание не фрагментарного, а единого управляющего модуля для обучения и развития персонала
B18: Предмет разработки | C18: Нейросетевой HRM-модуль
B19: Первый блок разработки | C19: Ядро HRM модуля
B20: Второй блок | C20: Модуль анализа компетенций
B21: Третий блок | C21: Модуль карьерных переходов
B22: Четвертый блок | C22: Рекомендательный модуль обучения
B23: Пятый блок | C23: Витрина данных, ETL и единая модель компетенций
B24: Шестой блок | C24: Интерфейсы и дашборды
B25: Седьмой блок | C25: Контур интеграций. Обеспечить обмен данными с HRM, LMS, BI, корпоративными API, а также формирование журналов событий, логирования и мониторинга.
B26: Восьмой блок | C26: Контур ИБ и защиты персональных данных
B28: Потребность в финансировании проекта
B29: Источник финансирования | C29: Сумма, руб.
B30: Всего вложений | C30: 276961520
B31: в т. ч. По источникам финансирования
B32: Собственные средства | C32: 276961520
B33: Заемные средства | C33: 0

Sheet Исходные данные
C2: Исходные данные:
C4: Система налогообложения: | D4: упрощенная система (доходы)
C5: Организационная форма бизнеса: | D5: ООО
C7: Временные показатели: | D7: Значение
C8: год | D8: № год
C9: месяц | D9: № мес.
F10: 1 год | R10: 2 год | AD10: 3 год | AP10: 4 год | BB10: 5 год | BN10: 6 год | BZ10: 7 год | CL10: 8 год | CX10: 9 год | DJ10: 10 год
C11: Наименование | D11: Ед. из. (мес. / руб.) | E11: Сумма | F11: 1 | G11: 2 | H11: 3 | I11: 4 | J11: 5 | K11: 6 | L11: 7 | M11: 8 | N11: 9 | O11: 10 | P11: 11 | Q11: 12 | R11: 1 | S11: 2 | T11: 3 | U11: 4 | V11: 5 | W11: 6 | X11: 7 | Y11: 8 | Z11: 9 | AA11: 10 | AB11: 11 | AC11: 12 | AD11: 1 | AE11: 2 | AF11: 3 | AG11: 4 | AH11: 5 | AI11: 6 | AJ11: 7 | AK11: 8 | AL11: 9 | AM11: 10 | AN11: 11 | AO11: 12 | AP11: 1 | AQ11: 2 | AR11: 3 | AS11: 4 | AT11: 5 | AU11: 6 | AV11: 7 | AW11: 8 | AX11: 9 | AY11: 10 | AZ11: 11 | BA11: 12 | BB11: 1 | BC11: 2 | BD11: 3 | BE11: 4 | BF11: 5 | BG11: 6 | BH11: 7 | BI11: 8 | BJ11: 9 | BK11: 10 | BL11: 11 | BM11: 12 | BN11: 1 | BO11: 2 | BP11: 3 | BQ11: 4 | BR11: 5 | BS11: 6 | BT11: 7 | BU11: 8 | BV11: 9 | BW11: 10 | BX11: 11 | BY11: 12 | BZ11: 1 | CA11: 2 | CB11: 3 | CC11: 4 | CD11: 5 | CE11: 6 | CF11: 7 | CG11: 8 | CH11: 9 | CI11: 10 | CJ11: 11 | CK11: 12 | CL11: 1 | CM11: 2 | CN11: 3 | CO11: 4 | CP11: 5 | CQ11: 6 | CR11: 7 | CS11: 8 | CT11: 9 | CU11: 10 | CV11: 11 | CW11: 12 | CX11: 1 | CY11: 2 | CZ11: 3 | DA11: 4 | DB11: 5 | DC11: 6 | DD11: 7 | DE11: 8 | DF11: 9 | DG11: 10 | DH11: 11 | DI11: 12 | DJ11: 1 | DK11: 2 | DL11: 3 | DM11: 4 | DN11: 5 | DO11: 6 | DP11: 7 | DQ11: 8 | DR11: 9 | DS11: 10 | DT11: 11 | DU11: 12
F12: 1 | G12: 2 | H12: 3 | I12: 4 | J12: 5 | K12: 6 | L12: 7 | M12: 8 | N12: 9 | O12: 10 | P12: 11 | Q12: 12 | R12: 13 | S12: 14 | T12: 15 | U12: 16 | V12: 17 | W12: 18 | X12: 19 | Y12: 20 | Z12: 21 | AA12: 22 | AB12: 23 | AC12: 24 | AD12: 25 | AE12: 26 | AF12: 27 | AG12: 28 | AH12: 29 | AI12: 30 | AJ12: 31 | AK12: 32 | AL12: 33 | AM12: 34 | AN12: 35 | AO12: 36 | AP12: 37 | AQ12: =AP12+1 -> 38 | AR12: =AQ12+1 -> 39 | AS12: =AR12+1 -> 40 | AT12: =AS12+1 -> 41 | AU12: =AT12+1 -> 42 | AV12: =AU12+1 -> 43 | AW12: =AV12+1 -> 44 | AX12: =AW12+1 -> 45 | ... DU12: =DT12+1 -> 120
C13: 1. Наименование вида налога и сбора
C14: ОСНО налог на прибыль | D14: % | E14: 0.05 | F14: 0.05 | G14: 0.05 | H14: 0.05 | I14: 0.05 | J14: 0.05 | K14: 0.05 | L14: 0.05 | M14: 0.05 | N14: 0.05 | O14: 0.05 | P14: 0.05 | Q14: 0.05 | R14: 0.05 | S14: 0.05 | T14: 0.05 | U14: 0.05 | V14: 0.05 | W14: 0.05 | X14: 0.05 | Y14: 0.05 | Z14: 0.05 | AA14: 0.05 | AB14: 0.05 | AC14: 0.05 | AD14: 0.05 | AE14: 0.05 | AF14: 0.05 | AG14: 0.05 | AH14: 0.05 | AI14: 0.05 | AJ14: 0.05 | AK14: 0.05 | AL14: 0.05 | AM14: 0.05 | AN14: 0.05 | AO14: 0.05 | AP14: 0.05 | AQ14: 0.05 | AR14: 0.05 | AS14: 0.05 | AT14: 0.05 | AU14: 0.05 | AV14: 0.05 | AW14: 0.05 | AX14: 0.05 | AY14: 0.05 | AZ14: 0.05 | BA14: 0.05 | BB14: 0.05 | BC14: 0.05 | BD14: 0.05 | BE14: 0.05 | BF14: 0.05 | BG14: 0.05 | BH14: 0.05 | BI14: 0.05 | BJ14: 0.05 | BK14: 0.05 | BL14: 0.05 | BM14: 0.05 | BN14: 0.05 | BO14: 0.05 | BP14: 0.05 | BQ14: 0.05 | BR14: 0.05 | BS14: 0.05 | BT14: 0.05 | BU14: 0.05 | BV14: 0.05 | BW14: 0.05 | BX14: 0.05 | BY14: 0.05 | BZ14: 0.05 | CA14: 0.05 | CB14: 0.05 | CC14: 0.05 | CD14: 0.05 | CE14: 0.05 | CF14: 0.05 | CG14: 0.05 | CH14: 0.05 | CI14: 0.05 | CJ14: 0.05 | CK14: 0.05 | CL14: 0.05 | CM14: 0.05 | CN14: 0.05 | CO14: 0.05 | CP14: 0.05 | CQ14: 0.05 | CR14: 0.05 | CS14: 0.05 | CT14: 0.05 | CU14: 0.05 | CV14: 0.05 | CW14: 0.05 | CX14: 0.05 | CY14: 0.05 | CZ14: 0.05 | DA14: 0.05 | DB14: 0.05 | DC14: 0.05 | DD14: 0.05 | DE14: 0.05 | DF14: 0.05 | DG14: 0.05 | DH14: 0.05 | DI14: 0.05 | DJ14: 0.05 | DK14: 0.05 | DL14: 0.05 | DM14: 0.05 | DN14: 0.05 | DO14: 0.05 | DP14: 0.05 | DQ14: 0.05 | DR14: 0.05 | DS14: 0.05 | DT14: 0.05 | DU14: 0.05
C15: Налог на имущество | D15: % | E15: 0.025 | F15: 0.00208 | G15: 0.00208 | H15: 0.00208 | I15: 0.00208 | J15: 0.00208 | K15: 0.00208 | L15: 0.00208 | M15: 0.00208 | N15: 0.00208 | O15: 0.00208 | P15: 0.00208 | Q15: 0.00208 | R15: 0.00208 | S15: 0.00208 | T15: 0.00208 | U15: 0.00208 | V15: 0.00208 | W15: 0.00208 | X15: 0.00208 | Y15: 0.00208 | Z15: 0.00208 | AA15: 0.00208 | AB15: 0.00208 | AC15: 0.00208 | AD15: 0.00208 | AE15: 0.00208 | AF15: 0.00208 | AG15: 0.00208 | AH15: 0.00208 | AI15: 0.00208 | AJ15: 0.00208 | AK15: 0.00208 | AL15: 0.00208 | AM15: 0.00208 | AN15: 0.00208 | AO15: 0.00208 | AP15: 0.00208 | AQ15: 0.00208 | AR15: 0.00208 | AS15: 0.00208 | AT15: 0.00208 | AU15: 0.00208 | AV15: 0.00208 | AW15: 0.00208 | AX15: 0.00208 | AY15: 0.00208 | AZ15: 0.00208 | BA15: 0.00208 | BB15: 0.00208 | BC15: 0.00208 | BD15: 0.00208 | BE15: 0.00208 | BF15: 0.00208 | BG15: 0.00208 | BH15: 0.00208 | BI15: 0.00208 | BJ15: 0.00208 | BK15: 0.00208 | BL15: 0.00208 | BM15: 0.00208 | BN15: 0.00208 | BO15: 0.00208 | BP15: 0.00208 | BQ15: 0.00208 | BR15: 0.00208 | BS15: 0.00208 | BT15: 0.00208 | BU15: 0.00208 | BV15: 0.00208 | BW15: 0.00208 | BX15: 0.00208 | BY15: 0.00208 | BZ15: 0.00208 | CA15: 0.00208 | CB15: 0.00208 | CC15: 0.00208 | CD15: 0.00208 | CE15: 0.00208 | CF15: 0.00208 | CG15: 0.00208 | CH15: 0.00208 | CI15: 0.00208 | CJ15: 0.00208 | CK15: 0.00208 | CL15: 0.00208 | CM15: 0.00208 | CN15: 0.00208 | CO15: 0.00208 | CP15: 0.00208 | CQ15: 0.00208 | CR15: 0.00208 | CS15: 0.00208 | CT15: 0.00208 | CU15: 0.00208 | CV15: 0.00208 | CW15: 0.00208 | CX15: 0.00208 | CY15: 0.00208 | CZ15: 0.00208 | DA15: 0.00208 | DB15: 0.00208 | DC15: 0.00208 | DD15: 0.00208 | DE15: 0.00208 | DF15: 0.00208 | DG15: 0.00208 | DH15: 0.00208 | DI15: 0.00208 | DJ15: 0.00208 | DK15: 0.00208 | DL15: 0.00208 | DM15: 0.00208 | DN15: 0.00208 | DO15: 0.00208 | DP15: 0.00208 | DQ15: 0.00208 | DR15: 0.00208 | DS15: 0.00208 | DT15: 0.00208 | DU15: 0.00208
C16: Налог на доходы физических лиц (НДФЛ) | D16: % | E16: 0.13 | F16: 0.13 | G16: 0.13 | H16: 0.13 | I16: 0.13 | J16: 0.13 | K16: 0.13 | L16: 0.13 | M16: 0.13 | N16: 0.13 | O16: 0.13 | P16: 0.13 | Q16: 0.13 | R16: 0.13 | S16: 0.13 | T16: 0.13 | U16: 0.13 | V16: 0.13 | W16: 0.13 | X16: 0.13 | Y16: 0.13 | Z16: 0.13 | AA16: 0.13 | AB16: 0.13 | AC16: 0.13 | AD16: 0.13 | AE16: 0.13 | AF16: 0.13 | AG16: 0.13 | AH16: 0.13 | AI16: 0.13 | AJ16: 0.13 | AK16: 0.13 | AL16: 0.13 | AM16: 0.13 | AN16: 0.13 | AO16: 0.13 | AP16: 0.13 | AQ16: 0.13 | AR16: 0.13 | AS16: 0.13 | AT16: 0.13 | AU16: 0.13 | AV16: 0.13 | AW16: 0.13 | AX16: 0.13 | AY16: 0.13 | AZ16: 0.13 | BA16: 0.13 | BB16: 0.13 | BC16: 0.13 | BD16: 0.13 | BE16: 0.13 | BF16: 0.13 | BG16: 0.13 | BH16: 0.13 | BI16: 0.13 | BJ16: 0.13 | BK16: 0.13 | BL16: 0.13 | BM16: 0.13 | BN16: 0.13 | BO16: 0.13 | BP16: 0.13 | BQ16: 0.13 | BR16: 0.13 | BS16: 0.13 | BT16: 0.13 | BU16: 0.13 | BV16: 0.13 | BW16: 0.13 | BX16: 0.13 | BY16: 0.13 | BZ16: 0.13 | CA16: 0.13 | CB16: 0.13 | CC16: 0.13 | CD16: 0.13 | CE16: 0.13 | CF16: 0.13 | CG16: 0.13 | CH16: 0.13 | CI16: 0.13 | CJ16: 0.13 | CK16: 0.13 | CL16: 0.13 | CM16: 0.13 | CN16: 0.13 | CO16: 0.13 | CP16: 0.13 | CQ16: 0.13 | CR16: 0.13 | CS16: 0.13 | CT16: 0.13 | CU16: 0.13 | CV16: 0.13 | CW16: 0.13 | CX16: 0.13 | CY16: 0.13 | CZ16: 0.13 | DA16: 0.13 | DB16: 0.13 | DC16: 0.13 | DD16: 0.13 | DE16: 0.13 | DF16: 0.13 | DG16: 0.13 | DH16: 0.13 | DI16: 0.13 | DJ16: 0.13 | DK16: 0.13 | DL16: 0.13 | DM16: 0.13 | DN16: 0.13 | DO16: 0.13 | DP16: 0.13 | DQ16: 0.13 | DR16: 0.13 | DS16: 0.13 | DT16: 0.13 | DU16: 0.13
C17: НДС | D17: % | E17: 0.18 | F17: 0.18 | G17: 0.18 | H17: 0.18 | I17: 0.18 | J17: 0.18 | K17: 0.18 | L17: 0.18 | M17: 0.18 | N17: 0.18 | O17: 0.18 | P17: 0.18 | Q17: 0.18 | R17: 0.18 | S17: 0.18 | T17: 0.18 | U17: 0.18 | V17: 0.18 | W17: 0.18 | X17: 0.18 | Y17: 0.18 | Z17: 0.18 | AA17: 0.18 | AB17: 0.18 | AC17: 0.18 | AD17: 0.18 | AE17: 0.18 | AF17: 0.18 | AG17: 0.18 | AH17: 0.18 | AI17: 0.18 | AJ17: 0.18 | AK17: 0.18 | AL17: 0.18 | AM17: 0.18 | AN17: 0.18 | AO17: 0.18 | AP17: 0.18 | AQ17: 0.18 | AR17: 0.18 | AS17: 0.18 | AT17: 0.18 | AU17: 0.18 | AV17: 0.18 | AW17: 0.18 | AX17: 0.18 | AY17: 0.18 | AZ17: 0.18 | BA17: 0.18 | BB17: 0.18 | BC17: 0.18 | BD17: 0.18 | BE17: 0.18 | BF17: 0.18 | BG17: 0.18 | BH17: 0.18 | BI17: 0.18 | BJ17: 0.18 | BK17: 0.18 | BL17: 0.18 | BM17: 0.18 | BN17: 0.18 | BO17: 0.18 | BP17: 0.18 | BQ17: 0.18 | BR17: 0.18 | BS17: 0.18 | BT17: 0.18 | BU17: 0.18 | BV17: 0.18 | BW17: 0.18 | BX17: 0.18 | BY17: 0.18 | BZ17: 0.18 | CA17: 0.18 | CB17: 0.18 | CC17: 0.18 | CD17: 0.18 | CE17: 0.18 | CF17: 0.18 | CG17: 0.18 | CH17: 0.18 | CI17: 0.18 | CJ17: 0.18 | CK17: 0.18 | CL17: 0.18 | CM17: 0.18 | CN17: 0.18 | CO17: 0.18 | CP17: 0.18 | CQ17: 0.18 | CR17: 0.18 | CS17: 0.18 | CT17: 0.18 | CU17: 0.18 | CV17: 0.18 | CW17: 0.18 | CX17: 0.18 | CY17: 0.18 | CZ17: 0.18 | DA17: 0.18 | DB17: 0.18 | DC17: 0.18 | DD17: 0.18 | DE17: 0.18 | DF17: 0.18 | DG17: 0.18 | DH17: 0.18 | DI17: 0.18 | DJ17: 0.18 | DK17: 0.18 | DL17: 0.18 | DM17: 0.18 | DN17: 0.18 | DO17: 0.18 | DP17: 0.18 | DQ17: 0.18 | DR17: 0.18 | DS17: 0.18 | DT17: 0.18 | DU17: 0.18
C18: Страховые взносы по персоналу: | D18: 7.6 | E18: 7.6 | F18: 7.6 | G18: 7.6 | H18: 7.6 | I18: 7.6 | J18: 7.6 | K18: 7.6 | L18: 7.6 | M18: 7.6 | N18: 7.6 | O18: 7.6 | P18: 7.6 | Q18: 7.6 | R18: 7.6 | S18: 7.6 | T18: 7.6 | U18: 7.6 | V18: 7.6 | W18: 7.6 | X18: 7.6 | Y18: 7.6 | Z18: 7.6 | AA18: 7.6 | AB18: 7.6 | AC18: 7.6 | AD18: 7.6 | AE18: 7.6 | AF18: 7.6 | AG18: 7.6 | AH18: 7.6 | AI18: 7.6 | AJ18: 7.6 | AK18: 7.6 | AL18: 7.6 | AM18: 7.6 | AN18: 7.6 | AO18: 7.6 | AP18: 7.6 | AQ18: 7.6 | AR18: 7.6 | AS18: 7.6 | AT18: 7.6 | AU18: 7.6 | AV18: 7.6 | AW18: 7.6 | AX18: 7.6 | AY18: 7.6 | AZ18: 7.6 | BA18: 7.6 | BB18: 7.6 | BC18: 7.6 | BD18: 7.6 | BE18: 7.6 | BF18: 7.6 | BG18: 7.6 | BH18: 7.6 | BI18: 7.6 | BJ18: 7.6 | BK18: 7.6 | BL18: 7.6 | BM18: 7.6 | BN18: 7.6 | BO18: 7.6 | BP18: 7.6 | BQ18: 7.6 | BR18: 7.6 | BS18: 7.6 | BT18: 7.6 | BU18: 7.6 | BV18: 7.6 | BW18: 7.6 | BX18: 7.6 | BY18: 7.6 | BZ18: 7.6 | CA18: 7.6 | CB18: 7.6 | CC18: 7.6 | CD18: 7.6 | CE18: 7.6 | CF18: 7.6 | CG18: 7.6 | CH18: 7.6 | CI18: 7.6 | CJ18: 7.6 | CK18: 7.6 | CL18: 7.6 | CM18: 7.6 | CN18: 7.6 | CO18: 7.6 | CP18: 7.6 | CQ18: 7.6 | CR18: 7.6 | CS18: 7.6 | CT18: 7.6 | CU18: 7.6 | CV18: 7.6 | CW18: 7.6 | CX18: 7.6 | CY18: 7.6 | CZ18: 7.6 | DA18: 7.6 | DB18: 7.6 | DC18: 7.6 | DD18: 7.6 | DE18: 7.6 | DF18: 7.6 | DG18: 7.6 | DH18: 7.6 | DI18: 7.6 | DJ18: 7.6 | DK18: 7.6 | DL18: 7.6 | DM18: 7.6 | DN18: 7.6 | DO18: 7.6 | DP18: 7.6 | DQ18: 7.6 | DR18: 7.6 | DS18: 7.6 | DT18: 7.6 | DU18: 7.6
C19: Пенсионный фонд (ПФР) | D19: % | E19: 0.06 | F19: 0.06 | G19: 0.06 | H19: 0.06 | I19: 0.06 | J19: 0.06 | K19: 0.06 | L19: 0.06 | M19: 0.06 | N19: 0.06 | O19: 0.06 | P19: 0.06 | Q19: 0.06 | R19: 0.06 | S19: 0.06 | T19: 0.06 | U19: 0.06 | V19: 0.06 | W19: 0.06 | X19: 0.06 | Y19: 0.06 | Z19: 0.06 | AA19: 0.06 | AB19: 0.06 | AC19: 0.06 | AD19: 0.06 | AE19: 0.06 | AF19: 0.06 | AG19: 0.06 | AH19: 0.06 | AI19: 0.06 | AJ19: 0.06 | AK19: 0.06 | AL19: 0.06 | AM19: 0.06 | AN19: 0.06 | AO19: 0.06 | AP19: 0.06 | AQ19: 0.06 | AR19: 0.06 | AS19: 0.06 | AT19: 0.06 | AU19: 0.06 | AV19: 0.06 | AW19: 0.06 | AX19: 0.06 | AY19: 0.06 | AZ19: 0.06 | BA19: 0.06 | BB19: 0.06 | BC19: 0.06 | BD19: 0.06 | BE19: 0.06 | BF19: 0.06 | BG19: 0.06 | BH19: 0.06 | BI19: 0.06 | BJ19: 0.06 | BK19: 0.06 | BL19: 0.06 | BM19: 0.06 | BN19: 0.06 | BO19: 0.06 | BP19: 0.06 | BQ19: 0.06 | BR19: 0.06 | BS19: 0.06 | BT19: 0.06 | BU19: 0.06 | BV19: 0.06 | BW19: 0.06 | BX19: 0.06 | BY19: 0.06 | BZ19: 0.06 | CA19: 0.06 | CB19: 0.06 | CC19: 0.06 | CD19: 0.06 | CE19: 0.06 | CF19: 0.06 | CG19: 0.06 | CH19: 0.06 | CI19: 0.06 | CJ19: 0.06 | CK19: 0.06 | CL19: 0.06 | CM19: 0.06 | CN19: 0.06 | CO19: 0.06 | CP19: 0.06 | CQ19: 0.06 | CR19: 0.06 | CS19: 0.06 | CT19: 0.06 | CU19: 0.06 | CV19: 0.06 | CW19: 0.06 | CX19: 0.06 | CY19: 0.06 | CZ19: 0.06 | DA19: 0.06 | DB19: 0.06 | DC19: 0.06 | DD19: 0.06 | DE19: 0.06 | DF19: 0.06 | DG19: 0.06 | DH19: 0.06 | DI19: 0.06 | DJ19: 0.06 | DK19: 0.06 | DL19: 0.06 | DM19: 0.06 | DN19: 0.06 | DO19: 0.06 | DP19: 0.06 | DQ19: 0.06 | DR19: 0.06 | DS19: 0.06 | DT19: 0.06 | DU19: 0.06
C20: Фонд социального страхования (ФСС) | D20: % | E20: 0.015 | F20: 0.015 | G20: 0.015 | H20: 0.015 | I20: 0.015 | J20: 0.015 | K20: 0.015 | L20: 0.015 | M20: 0.015 | N20: 0.015 | O20: 0.015 | P20: 0.015 | Q20: 0.015 | R20: 0.015 | S20: 0.015 | T20: 0.015 | U20: 0.015 | V20: 0.015 | W20: 0.015 | X20: 0.015 | Y20: 0.015 | Z20: 0.015 | AA20: 0.015 | AB20: 0.015 | AC20: 0.015 | AD20: 0.015 | AE20: 0.015 | AF20: 0.015 | AG20: 0.015 | AH20: 0.015 | AI20: 0.015 | AJ20: 0.015 | AK20: 0.015 | AL20: 0.015 | AM20: 0.015 | AN20: 0.015 | AO20: 0.015 | AP20: 0.015 | AQ20: 0.015 | AR20: 0.015 | AS20: 0.015 | AT20: 0.015 | AU20: 0.015 | AV20: 0.015 | AW20: 0.015 | AX20: 0.015 | AY20: 0.015 | AZ20: 0.015 | BA20: 0.015 | BB20: 0.015 | BC20: 0.015 | BD20: 0.015 | BE20: 0.015 | BF20: 0.015 | BG20: 0.015 | BH20: 0.015 | BI20: 0.015 | BJ20: 0.015 | BK20: 0.015 | BL20: 0.015 | BM20: 0.015 | BN20: 0.015 | BO20: 0.015 | BP20: 0.015 | BQ20: 0.015 | BR20: 0.015 | BS20: 0.015 | BT20: 0.015 | BU20: 0.015 | BV20: 0.015 | BW20: 0.015 | BX20: 0.015 | BY20: 0.015 | BZ20: 0.015 | CA20: 0.015 | CB20: 0.015 | CC20: 0.015 | CD20: 0.015 | CE20: 0.015 | CF20: 0.015 | CG20: 0.015 | CH20: 0.015 | CI20: 0.015 | CJ20: 0.015 | CK20: 0.015 | CL20: 0.015 | CM20: 0.015 | CN20: 0.015 | CO20: 0.015 | CP20: 0.015 | CQ20: 0.015 | CR20: 0.015 | CS20: 0.015 | CT20: 0.015 | CU20: 0.015 | CV20: 0.015 | CW20: 0.015 | CX20: 0.015 | CY20: 0.015 | CZ20: 0.015 | DA20: 0.015 | DB20: 0.015 | DC20: 0.015 | DD20: 0.015 | DE20: 0.015 | DF20: 0.015 | DG20: 0.015 | DH20: 0.015 | DI20: 0.015 | DJ20: 0.015 | DK20: 0.015 | DL20: 0.015 | DM20: 0.015 | DN20: 0.015 | DO20: 0.015 | DP20: 0.015 | DQ20: 0.015 | DR20: 0.015 | DS20: 0.015 | DT20: 0.015 | DU20: 0.015
C21: Фонд обязательного медицинского страхования (ФОМС) | D21: % | E21: 0.001 | F21: 0.001 | G21: 0.001 | H21: 0.001 | I21: 0.001 | J21: 0.001 | K21: 0.001 | L21: 0.001 | M21: 0.001 | N21: 0.001 | O21: 0.001 | P21: 0.001 | Q21: 0.001 | R21: 0.001 | S21: 0.001 | T21: 0.001 | U21: 0.001 | V21: 0.001 | W21: 0.001 | X21: 0.001 | Y21: 0.001 | Z21: 0.001 | AA21: 0.001 | AB21: 0.001 | AC21: 0.001 | AD21: 0.001 | AE21: 0.001 | AF21: 0.001 | AG21: 0.001 | AH21: 0.001 | AI21: 0.001 | AJ21: 0.001 | AK21: 0.001 | AL21: 0.001 | AM21: 0.001 | AN21: 0.001 | AO21: 0.001 | AP21: 0.001 | AQ21: 0.001 | AR21: 0.001 | AS21: 0.001 | AT21: 0.001 | AU21: 0.001 | AV21: 0.001 | AW21: 0.001 | AX21: 0.001 | AY21: 0.001 | AZ21: 0.001 | BA21: 0.001 | BB21: 0.001 | BC21: 0.001 | BD21: 0.001 | BE21: 0.001 | BF21: 0.001 | BG21: 0.001 | BH21: 0.001 | BI21: 0.001 | BJ21: 0.001 | BK21: 0.001 | BL21: 0.001 | BM21: 0.001 | BN21: 0.001 | BO21: 0.001 | BP21: 0.001 | BQ21: 0.001 | BR21: 0.001 | BS21: 0.001 | BT21: 0.001 | BU21: 0.001 | BV21: 0.001 | BW21: 0.001 | BX21: 0.001 | BY21: 0.001 | BZ21: 0.001 | CA21: 0.001 | CB21: 0.001 | CC21: 0.001 | CD21: 0.001 | CE21: 0.001 | CF21: 0.001 | CG21: 0.001 | CH21: 0.001 | CI21: 0.001 | CJ21: 0.001 | CK21: 0.001 | CL21: 0.001 | CM21: 0.001 | CN21: 0.001 | CO21: 0.001 | CP21: 0.001 | CQ21: 0.001 | CR21: 0.001 | CS21: 0.001 | CT21: 0.001 | CU21: 0.001 | CV21: 0.001 | CW21: 0.001 | CX21: 0.001 | CY21: 0.001 | CZ21: 0.001 | DA21: 0.001 | DB21: 0.001 | DC21: 0.001 | DD21: 0.001 | DE21: 0.001 | DF21: 0.001 | DG21: 0.001 | DH21: 0.001 | DI21: 0.001 | DJ21: 0.001 | DK21: 0.001 | DL21: 0.001 | DM21: 0.001 | DN21: 0.001 | DO21: 0.001 | DP21: 0.001 | DQ21: 0.001 | DR21: 0.001 | DS21: 0.001 | DT21: 0.001 | DU21: 0.001
C22: Страховые взносы по ООО^ | D22: руб. | E22: =SUM(F22:DU22) -> 5.4721566e+09 | F22: =SUM(F23:F25) -> 45613047 | G22: =SUM(G23:G25) -> 45613047 | H22: =SUM(H23:H25) -> 45613047 | I22: =SUM(I23:I25) -> 45613047 | J22: =SUM(J23:J25) -> 45613047 | K22: =SUM(K23:K25) -> 45613047 | L22: =SUM(L23:L25) -> 45613047 | M22: =SUM(M23:M25) -> 45613047 | ... DU22: =SUM(DU23:DU25) -> 45600000
C23: Пенсионный фонд (ПФР) | D23: руб. | E23: =SUM(F23:DU23) -> 4.3201236e+09 | F23: =F33*F19 -> 36010300 | G23: =G33*G19 -> 36010300 | H23: =H33*H19 -> 36010300 | I23: =I33*I19 -> 36010300 | J23: =J33*J19 -> 36010300 | K23: =K33*K19 -> 36010300 | L23: =L33*L19 -> 36010300 | M23: =M33*M19 -> 36010300 | ... DU23: =DU33*DU19 -> 36000000
C24: Фонд обязательного медицинского страхования (ФОМС) | D24: руб. | E24: =SUM(F24:DU24) -> 1.0800309e+09 | F24: =F33*F20 -> 9002575 | G24: =G33*G20 -> 9002575 | H24: =H33*H20 -> 9002575 | I24: =I33*I20 -> 9002575 | J24: =J33*J20 -> 9002575 | K24: =K33*K20 -> 9002575 | L24: =L33*L20 -> 9002575 | M24: =M33*M20 -> 9002575 | ... DU24: =DU33*DU20 -> 9000000
C25: Медицинские взносы | D25: руб. | E25: =SUM(F25:DU25) -> 72002060 | F25: =F33*F21 -> 600171.67 | G25: =G33*G21 -> 600171.67 | H25: =H33*H21 -> 600171.67 | I25: =I33*I21 -> 600171.67 | J25: =J33*J21 -> 600171.67 | K25: =K33*K21 -> 600171.67 | L25: =L33*L21 -> 600171.67 | M25: =M33*M21 -> 600171.67 | ... DU25: =DU33*DU21 -> 600000
C26: 2. Коэффициенты
C27: Ключевая ставка ЦБ РФ | D27: % | E27: 14.5
C28: Рентабельность проекта | D28: % | E28: 23.33
C29: 3. Инвестиции в проект
C30: 3.1. Капитальные затраты | D30: руб. | E30: =SUM(F30:DU30) -> 0 | F30: 0 | G30: 0 | H30: 0 | I30: 0 | J30: 0 | K30: 0 | L30: 0 | M30: 0 | N30: 0 | O30: 0 | P30: 0 | Q30: 0 | R30: 0 | S30: 0 | T30: 0 | U30: 0 | V30: 0 | W30: 0 | X30: 0 | Y30: 0 | Z30: 0 | AA30: 0 | AB30: 0 | AC30: 0 | AD30: 0 | AE30: 0 | AF30: 0 | AG30: 0 | AH30: 0 | AI30: 0 | AJ30: 0 | AK30: 0 | AL30: 0 | AM30: 0 | AN30: 0 | AO30: 0 | AP30: 0 | AQ30: 0 | AR30: 0 | AS30: 0 | AT30: 0 | AU30: 0 | AV30: 0 | AW30: 0 | AX30: 0 | AY30: 0 | AZ30: 0 | BA30: 0 | BB30: 0 | BC30: 0 | BD30: 0 | BE30: 0 | BF30: 0 | BG30: 0 | BH30: 0 | BI30: 0 | BJ30: 0 | BK30: 0 | BL30: 0 | BM30: 0 | BN30: 0 | BO30: 0 | BP30: 0 | BQ30: 0 | BR30: 0 | BS30: 0 | BT30: 0 | BU30: 0 | BV30: 0 | BW30: 0 | BX30: 0 | BY30: 0 | BZ30: 0 | CA30: 0 | CB30: 0 | CC30: 0 | CD30: 0 | CE30: 0 | CF30: 0 | CG30: 0 | CH30: 0 | CI30: 0 | CJ30: 0 | CK30: 0 | CL30: 0 | CM30: 0 | CN30: 0 | CO30: 0 | CP30: 0 | CQ30: 0 | CR30: 0 | CS30: 0 | CT30: 0 | CU30: 0 | CV30: 0 | CW30: 0 | CX30: 0 | CY30: 0 | CZ30: 0 | DA30: 0 | DB30: 0 | DC30: 0 | DD30: 0 | DE30: 0 | DF30: 0 | DG30: 0 | DH30: 0 | DI30: 0 | DJ30: 0 | DK30: 0 | DL30: 0 | DM30: 0 | DN30: 0 | DO30: 0 | DP30: 0 | DQ30: 0 | DR30: 0 | DS30: 0 | DT30: 0 | DU30: 0
C31: 3.2. Операционные затраты | D31: руб. | E31: =SUM(E32:E34) -> 2.1604282e+10 | F31: =F32+F33+F34 -> 600171666 | G31: =G32+G33+G34 -> 600171666 | H31: =H32+H33+H34 -> 600171666 | I31: =I32+I33+I34 -> 600171666 | J31: =J32+J33+J34 -> 600171666 | K31: =K32+K33+K34 -> 600171666 | L31: =L32+L33+L34 -> 600171666 | M31: =M32+M33+M34 -> 600171666 | ... DU31: =DU32+DU33+DU34 -> 6.0009259e+08
C32: 3.2.1. Текущие затраты | D32: руб. | E32: =SUM(F32:AO32) -> 2222222.4 | F32: ='Операционные затраты'!E8 -> 0 | G32: 0 | H32: 0 | I32: 0 | J32: 0 | K32: 0 | L32: 0 | M32: 0 | N32: 0 | O32: 0 | P32: 0 | Q32: 0 | R32: 92592.6 | S32: 92592.6 | T32: 92592.6 | U32: 92592.6 | V32: 92592.6 | W32: 92592.6 | X32: 92592.6 | Y32: 92592.6 | Z32: 92592.6 | AA32: 92592.6 | AB32: 92592.6 | AC32: 92592.6 | AD32: 92592.6 | AE32: 92592.6 | AF32: 92592.6 | AG32: 92592.6 | AH32: 92592.6 | AI32: 92592.6 | AJ32: 92592.6 | AK32: 92592.6 | AL32: 92592.6 | AM32: 92592.6 | AN32: 92592.6 | AO32: 92592.6 | AP32: 92592.6 | AQ32: 92592.6 | AR32: 92592.6 | AS32: 92592.6 | AT32: 92592.6 | AU32: 92592.6 | AV32: 92592.6 | AW32: 92592.6 | AX32: 92592.6 | AY32: 92592.6 | AZ32: 92592.6 | BA32: 92592.6 | BB32: 92592.6 | BC32: 92592.6 | BD32: 92592.6 | BE32: 92592.6 | BF32: 92592.6 | BG32: 92592.6 | BH32: 92592.6 | BI32: 92592.6 | BJ32: 92592.6 | BK32: 92592.6 | BL32: 92592.6 | BM32: 92592.6 | BN32: 92592.6 | BO32: 92592.6 | BP32: 92592.6 | BQ32: 92592.6 | BR32: 92592.6 | BS32: 92592.6 | BT32: 92592.6 | BU32: 92592.6 | BV32: 92592.6 | BW32: 92592.6 | BX32: 92592.6 | BY32: 92592.6 | BZ32: 92592.6 | CA32: 92592.6 | CB32: 92592.6 | CC32: 92592.6 | CD32: 92592.6 | CE32: 92592.6 | CF32: 92592.6 | CG32: 92592.6 | CH32: 92592.6 | CI32: 92592.6 | CJ32: 92592.6 | CK32: 92592.6 | CL32: 92592.6 | CM32: 92592.6 | CN32: 92592.6 | CO32: 92592.6 | CP32: 92592.6 | CQ32: 92592.6 | CR32: 92592.6 | CS32: 92592.6 | CT32: 92592.6 | CU32: 92592.6 | CV32: 92592.6 | CW32: 92592.6 | CX32: 92592.6 | CY32: 92592.6 | CZ32: 92592.6 | DA32: 92592.6 | DB32: 92592.6 | DC32: 92592.6 | DD32: 92592.6 | DE32: 92592.6 | DF32: 92592.6 | DG32: 92592.6 | DH32: 92592.6 | DI32: 92592.6 | DJ32: 92592.6 | DK32: 92592.6 | DL32: 92592.6 | DM32: 92592.6 | DN32: 92592.6 | DO32: 92592.6 | DP32: 92592.6 | DQ32: 92592.6 | DR32: 92592.6 | DS32: 92592.6 | DT32: 92592.6 | DU32: 92592.6
C33: 3.2.2.Административные затраты | D33: руб. | E33: =SUM(F33:AO33) -> 21602059992 | F33: =SUM('Операционные затраты'!E8,'Операционные затраты'!E22,'Операционные затраты'!E24) -> 600171666 | G33: =SUM('Операционные затраты'!F8,'Операционные затраты'!F22,'Операционные затраты'!F24) -> 600171666 | H33: =SUM('Операционные затраты'!G8,'Операционные затраты'!G22,'Операционные затраты'!G24) -> 600171666 | I33: =SUM('Операционные затраты'!H8,'Операционные затраты'!H22,'Операционные затраты'!H24) -> 600171666 | J33: =SUM('Операционные затраты'!I8,'Операционные затраты'!I22,'Операционные затраты'!I24) -> 600171666 | K33: =SUM('Операционные затраты'!J8,'Операционные затраты'!J22,'Операционные затраты'!J24) -> 600171666 | L33: =SUM('Операционные затраты'!K8,'Операционные затраты'!K22,'Операционные затраты'!K24) -> 600171666 | M33: =SUM('Операционные затраты'!L8,'Операционные затраты'!L22,'Операционные затраты'!L24) -> 600171666 | ... DU33: =SUM('Операционные затраты'!DT8,'Операционные затраты'!DT22,'Операционные затраты'!DT24) -> 600000000
C34: 3.2.3. Прочие расходы | D34: руб. | E34: =SUM(F34:AO34) -> 0 | F34: 0 | G34: 0 | H34: 0 | I34: 0 | J34: 0 | K34: 0 | L34: 0 | M34: 0 | N34: 0 | O34: 0 | P34: 0 | Q34: 0 | R34: 0 | S34: 0 | T34: 0 | U34: 0 | V34: 0 | W34: 0 | X34: 0 | Y34: 0 | Z34: 0 | AA34: 0 | AB34: 0 | AC34: 0 | AD34: 0 | AE34: 0 | AF34: 0 | AG34: 0 | AH34: 0 | AI34: 0 | AJ34: 0 | AK34: 0 | AL34: 0 | AM34: 0 | AN34: 0 | AO34: 0 | AP34: 0 | AQ34: 0 | AR34: 0 | AS34: 0 | AT34: 0 | AU34: 0 | AV34: 0 | AW34: 0 | AX34: 0 | AY34: 0 | AZ34: 0 | BA34: 0 | BB34: 0 | BC34: 0 | BD34: 0 | BE34: 0 | BF34: 0 | BG34: 0 | BH34: 0 | BI34: 0 | BJ34: 0 | BK34: 0 | BL34: 0 | BM34: 0 | BN34: 0 | BO34: 0 | BP34: 0 | BQ34: 0 | BR34: 0 | BS34: 0 | BT34: 0 | BU34: 0 | BV34: 0 | BW34: 0 | BX34: 0 | BY34: 0 | BZ34: 0 | CA34: 0 | CB34: 0 | CC34: 0 | CD34: 0 | CE34: 0 | CF34: 0 | CG34: 0 | CH34: 0 | CI34: 0 | CJ34: 0 | CK34: 0 | CL34: 0 | CM34: 0 | CN34: 0 | CO34: 0 | CP34: 0 | CQ34: 0 | CR34: 0 | CS34: 0 | CT34: 0 | CU34: 0 | CV34: 0 | CW34: 0 | CX34: 0 | CY34: 0 | CZ34: 0 | DA34: 0 | DB34: 0 | DC34: 0 | DD34: 0 | DE34: 0 | DF34: 0 | DG34: 0 | DH34: 0 | DI34: 0 | DJ34: 0 | DK34: 0 | DL34: 0 | DM34: 0 | DN34: 0 | DO34: 0 | DP34: 0 | DQ34: 0 | DR34: 0 | DS34: 0 | DT34: 0 | DU34: 0
C36: Заемные средства | D36: руб. | E36: =SUM(F36:I36) -> 0 | F36: 0 | G36: 0 | H36: 0 | I36: 0 | J36: 0 | K36: 0 | L36: 0 | M36: 0 | N36: 0 | O36: 0 | P36: 0 | Q36: 0 | R36: 0 | S36: 0 | T36: 0 | U36: 0 | V36: 0 | W36: 0 | X36: 0 | Y36: 0 | Z36: 0 | AA36: 0 | AB36: 0 | AC36: 0 | AD36: 0 | AE36: 0 | AF36: 0 | AG36: 0 | AH36: 0 | AI36: 0 | AJ36: 0 | AK36: 0 | AL36: 0 | AM36: 0 | AN36: 0 | AO36: 0 | AP36: 0 | AQ36: 0 | AR36: 0 | AS36: 0 | AT36: 0 | AU36: 0 | AV36: 0 | AW36: 0 | AX36: 0 | AY36: 0 | AZ36: 0 | BA36: 0 | BB36: 0 | BC36: 0 | BD36: 0 | BE36: 0 | BF36: 0 | BG36: 0 | BH36: 0 | BI36: 0 | BJ36: 0 | BK36: 0 | BL36: 0 | BM36: 0 | BN36: 0 | BO36: 0 | BP36: 0 | BQ36: 0 | BR36: 0 | BS36: 0 | BT36: 0 | BU36: 0 | BV36: 0 | BW36: 0 | BX36: 0 | BY36: 0 | BZ36: 0 | CA36: 0 | CB36: 0 | CC36: 0 | CD36: 0 | CE36: 0 | CF36: 0 | CG36: 0 | CH36: 0 | CI36: 0 | CJ36: 0 | CK36: 0 | CL36: 0 | CM36: 0 | CN36: 0 | CO36: 0 | CP36: 0 | CQ36: 0 | CR36: 0 | CS36: 0 | CT36: 0 | CU36: 0 | CV36: 0 | CW36: 0 | CX36: 0 | CY36: 0 | CZ36: 0 | DA36: 0 | DB36: 0 | DC36: 0 | DD36: 0 | DE36: 0 | DF36: 0 | DG36: 0 | DH36: 0 | DI36: 0 | DJ36: 0 | DK36: 0 | DL36: 0 | DM36: 0 | DN36: 0 | DO36: 0 | DP36: 0 | DQ36: 0 | DR36: 0 | DS36: 0 | DT36: 0 | DU36: 0
C37: 4. Источники финансирования:
C38: Доля собственных средств | D38: %, 100 | E38: =SUM(F38:DU38) -> 276961520 | F38: 276961520 | G38: 0 | H38: 0 | I38: 0 | J38: 0 | K38: 0 | L38: 0 | M38: 0 | N38: 0 | O38: 0 | P38: 0 | Q38: 0 | R38: 0 | S38: 0 | T38: 0 | U38: 0 | V38: 0 | W38: 0 | X38: 0 | Y38: 0 | Z38: 0 | AA38: 0 | AB38: 0 | AC38: 0 | AD38: 0 | AE38: 0 | AF38: 0 | AG38: 0 | AH38: 0 | AI38: 0 | AJ38: 0 | AK38: 0 | AL38: 0 | AM38: 0 | AN38: 0 | AO38: 0 | AP38: 0 | AQ38: =AQ30 -> 0 | AR38: =AR30 -> 0 | AS38: =AS30 -> 0 | AT38: =AT30 -> 0 | AU38: =AU30 -> 0 | AV38: =AV30 -> 0 | AW38: =AW30 -> 0 | AX38: =AX30 -> 0 | ... DU38: =DU30 -> 0
C39: Доля заемных средств, вкладываемых в производство | D39: % | E39: 0 | F39: 0 | G39: 0 | H39: 0 | I39: 0 | J39: 0 | K39: 0 | L39: 0 | M39: 0 | N39: 0 | O39: 0 | P39: 0 | Q39: 0 | R39: 0 | S39: 0 | T39: 0 | U39: 0 | V39: 0 | W39: 0 | X39: 0 | Y39: 0 | Z39: 0 | AA39: 0 | AB39: 0 | AC39: 0 | AD39: 0 | AE39: 0 | AF39: 0 | AG39: 0 | AH39: 0 | AI39: 0 | AJ39: 0 | AK39: 0 | AL39: 0 | AM39: 0 | AN39: 0 | AO39: 0 | AP39: 0 | AQ39: 0 | AR39: 0 | AS39: 0 | AT39: 0 | AU39: 0 | AV39: 0 | AW39: 0 | AX39: 0 | AY39: 0 | AZ39: 0 | BA39: 0 | BB39: 0 | BC39: 0 | BD39: 0 | BE39: 0 | BF39: 0 | BG39: 0 | BH39: 0 | BI39: 0 | BJ39: 0 | BK39: 0 | BL39: 0 | BM39: 0 | BN39: 0 | BO39: 0 | BP39: 0 | BQ39: 0 | BR39: 0 | BS39: 0 | BT39: 0 | BU39: 0 | BV39: 0 | BW39: 0 | BX39: 0 | BY39: 0 | BZ39: 0 | CA39: 0 | CB39: 0 | CC39: 0 | CD39: 0 | CE39: 0 | CF39: 0 | CG39: 0 | CH39: 0 | CI39: 0 | CJ39: 0 | CK39: 0 | CL39: 0 | CM39: 0 | CN39: 0 | CO39: 0 | CP39: 0 | CQ39: 0 | CR39: 0 | CS39: 0 | CT39: 0 | CU39: 0 | CV39: 0 | CW39: 0 | CX39: 0 | CY39: 0 | CZ39: 0 | DA39: 0 | DB39: 0 | DC39: 0 | DD39: 0 | DE39: 0 | DF39: 0 | DG39: 0 | DH39: 0 | DI39: 0 | DJ39: 0 | DK39: 0 | DL39: 0 | DM39: 0 | DN39: 0 | DO39: 0 | DP39: 0 | DQ39: 0 | DR39: 0 | DS39: 0 | DT39: 0 | DU39: 0
C40: 5. Индекс инфляции | D40: % | E40: 0.145 | F40: =(1+(1+$E$40)^(1/12)-1)^1 -> 1.0113476 | G40: =(1+(1+$E$40)^(1/12)-1)^2 -> 1.022824 | H40: =(1+(1+$E$40)^(1/12)-1)^3 -> 1.0344306 | I40: =(1+(1+$E$40)^(1/12)-1)^4 -> 1.046169 | J40: =(1+(1+$E$40)^(1/12)-1)^5 -> 1.0580405 | K40: =(1+(1+$E$40)^(1/12)-1)^6 -> 1.0700467 | L40: =(1+(1+$E$40)^(1/12)-1)^7 -> 1.0821892 | M40: =(1+(1+$E$40)^(1/12)-1)^8 -> 1.0944695 | N40: =(1+(1+$E$40)^(1/12)-1)^9 -> 1.1068891 | O40: =(1+(1+$E$40)^(1/12)-1)^10 -> 1.1194497 | P40: =(1+(1+$E$40)^(1/12)-1)^11 -> 1.1321528 | Q40: =(1+(1+$E$40)^(1/12)-1)^12 -> 1.145 | R40: =(1+(1+$E$40)^(1/12)-1)^13 -> 1.157993 | S40: =(1+(1+$E$40)^(1/12)-1)^14 -> 1.1711335 | T40: =(1+(1+$E$40)^(1/12)-1)^15 -> 1.1844231 | U40: =(1+(1+$E$40)^(1/12)-1)^16 -> 1.1978635 | V40: =(1+(1+$E$40)^(1/12)-1)^17 -> 1.2114564 | W40: =(1+(1+$E$40)^(1/12)-1)^18 -> 1.2252035 | X40: =(1+(1+$E$40)^(1/12)-1)^19 -> 1.2391066 | Y40: =(1+(1+$E$40)^(1/12)-1)^20 -> 1.2531676 | Z40: =(1+(1+$E$40)^(1/12)-1)^Z12 -> 1.267388 | AA40: =(1+(1+$E$40)^(1/12)-1)^AA12 -> 1.2817699 | AB40: =(1+(1+$E$40)^(1/12)-1)^AB12 -> 1.2963149 | AC40: =(1+(1+$E$40)^(1/12)-1)^AC12 -> 1.311025 | AD40: =(1+(1+$E$40)^(1/12)-1)^AD12 -> 1.325902 | AE40: =(1+(1+$E$40)^(1/12)-1)^AE12 -> 1.3409478 | AF40: =(1+(1+$E$40)^(1/12)-1)^AF12 -> 1.3561644 | AG40: =(1+(1+$E$40)^(1/12)-1)^AG12 -> 1.3715537 | ... DU40: =(1+(1+$E$40)^(1/12)-1)^DU12 -> 3.8730657
C41: 6. Основные средства | D41: руб. | E41: =SUM(F41:DU41) -> 355200000000000 | F41: ='Амортизация, до'!I18 -> 2960000000000 | G41: ='Амортизация, до'!J18 -> 2960000000000 | H41: ='Амортизация, до'!K18 -> 2960000000000 | I41: ='Амортизация, до'!L18 -> 2960000000000 | J41: ='Амортизация, до'!M18 -> 2960000000000 | K41: ='Амортизация, до'!N18 -> 2960000000000 | L41: ='Амортизация, до'!O18 -> 2960000000000 | M41: ='Амортизация, до'!P18 -> 2960000000000 | ... DU41: ='Амортизация, до'!DX18 -> 2960000000000
C42: 7. Амортизация | D42: руб. | E42: =SUM(F42:DU42) -> 8.400565e+11 | F42: ='Амортизация, до'!I17 -> 8222288000 | G42: ='Амортизация, до'!J17 -> 8.1994481e+09 | H42: ='Амортизация, до'!K17 -> 8.1766717e+09 | I42: ='Амортизация, до'!L17 -> 8.1539585e+09 | J42: ='Амортизация, до'!M17 -> 8.1313085e+09 | K42: ='Амортизация, до'!N17 -> 8.1087213e+09 | L42: ='Амортизация, до'!O17 -> 8.0861969e+09 | M42: ='Амортизация, до'!P17 -> 8.0637351e+09 | ... DU42: ='Амортизация, до'!DX17 -> 5.9051825e+09

Sheet Выручка, до
A1: Выручка до внедрения
D2: 1 год | P2: 2 год | AB2: 3 год | AN2: 4 год | AZ2: 5 год | BL2: 6 год | BX2: 7 год | CJ2: 8 год | CV2: 9 год | DH2: 10 год
A3: Показатель | B3: Ед. из. | C3: Сумма | D3: 1 | E3: 2 | F3: 3 | G3: 4 | H3: 5 | I3: 6 | J3: 7 | K3: 8 | L3: 9 | M3: 10 | N3: 11 | O3: 12 | P3: 1 | Q3: 2 | R3: 3 | S3: 4 | T3: 5 | U3: 6 | V3: 7 | W3: 8 | X3: 9 | Y3: 10 | Z3: 11 | AA3: 12 | AB3: 1 | AC3: 2 | AD3: 3 | AE3: 4 | AF3: 5 | AG3: 6 | AH3: 7 | AI3: 8 | AJ3: 9 | AK3: 10 | AL3: 11 | AM3: 12 | AN3: 1 | AO3: 2 | AP3: 3 | AQ3: 4 | AR3: 5 | AS3: 6 | AT3: 7 | AU3: 8 | AV3: 9 | AW3: 10 | AX3: 11 | AY3: 12 | AZ3: 1 | BA3: 2 | BB3: 3 | BC3: 4 | BD3: 5 | BE3: 6 | BF3: 7 | BG3: 8 | BH3: 9 | BI3: 10 | BJ3: 11 | BK3: 12 | BL3: 1 | BM3: 2 | BN3: 3 | BO3: 4 | BP3: 5 | BQ3: 6 | BR3: 7 | BS3: 8 | BT3: 9 | BU3: 10 | BV3: 11 | BW3: 12 | BX3: 1 | BY3: 2 | BZ3: 3 | CA3: 4 | CB3: 5 | CC3: 6 | CD3: 7 | CE3: 8 | CF3: 9 | CG3: 10 | CH3: 11 | CI3: 12 | CJ3: 1 | CK3: 2 | CL3: 3 | CM3: 4 | CN3: 5 | CO3: 6 | CP3: 7 | CQ3: 8 | CR3: 9 | CS3: 10 | CT3: 11 | CU3: 12 | CV3: 1 | CW3: 2 | CX3: 3 | CY3: 4 | CZ3: 5 | DA3: 6 | DB3: 7 | DC3: 8 | DD3: 9 | DE3: 10 | DF3: 11 | DG3: 12 | DH3: 1 | DI3: 2 | DJ3: 3 | DK3: 4 | DL3: 5 | DM3: 6 | DN3: 7 | DO3: 8 | DP3: 9 | DQ3: 10 | DR3: 11 | DS3: 12
D4: 1 | E4: 2 | F4: 3 | G4: 4 | H4: 5 | I4: 6 | J4: 7 | K4: 8 | L4: 9 | M4: 10 | N4: 11 | O4: 12 | P4: 13 | Q4: 14 | R4: 15 | S4: 16 | T4: 17 | U4: 18 | V4: 19 | W4: 20 | X4: 21 | Y4: 22 | Z4: 23 | AA4: 24 | AB4: 25 | AC4: 26 | AD4: 27 | AE4: 28 | AF4: 29 | AG4: 30 | AH4: 31 | AI4: 32 | AJ4: 33 | AK4: 34 | AL4: 35 | AM4: 36 | AN4: 1 | AO4: 2 | AP4: 3 | AQ4: 4 | AR4: 5 | AS4: 6 | AT4: 7 | AU4: 8 | AV4: 9 | AW4: 10 | AX4: 11 | AY4: 12 | AZ4: 13 | BA4: 14 | BB4: 15 | BC4: 16 | BD4: 17 | BE4: 18 | BF4: 19 | BG4: 20 | BH4: 21 | BI4: 22 | BJ4: 23 | BK4: 24 | BL4: 1 | BM4: 2 | BN4: 3 | BO4: 4 | BP4: 5 | BQ4: 6 | BR4: 7 | BS4: 8 | BT4: 9 | BU4: 10 | BV4: 11 | BW4: 12 | BX4: 13 | BY4: 14 | BZ4: 15 | CA4: 16 | CB4: 17 | CC4: 18 | CD4: 19 | CE4: 20 | CF4: 21 | CG4: 22 | CH4: 23 | CI4: 24 | CJ4: 25 | CK4: 26 | CL4: 27 | CM4: 28 | CN4: 29 | CO4: 30 | CP4: 31 | CQ4: 32 | CR4: 33 | CS4: 34 | CT4: 35 | CU4: 36 | CV4: 1 | CW4: 2 | CX4: 3 | CY4: 4 | CZ4: 5 | DA4: 6 | DB4: 7 | DC4: 8 | DD4: 9 | DE4: 10 | DF4: 11 | DG4: 12 | DH4: 13 | DI4: 14 | DJ4: 15 | DK4: 16 | DL4: 17 | DM4: 18 | DN4: 19 | DO4: 20 | DP4: 21 | DQ4: 22 | DR4: 23 | DS4: 24
A5: Количество клиентов | B5: чел. | C5: =SUM(D5:DS5) -> 2.087913e+09 | D5: 9076356 | E5: =1.01*D5 -> 9167119.6 | F5: =1.01*E5 -> 9258790.8 | G5: =1.01*F5 -> 9351378.7 | H5: =1.01*G5 -> 9444892.4 | I5: =1.01*H5 -> 9539341.4 | J5: =1.01*I5 -> 9634734.8 | K5: =1.01*J5 -> 9731082.1 | L5: =1.01*K5 -> 9828393 | ... DS5: =1.01*DR5 -> 29658897
A6: Средний чек | B6: руб. | C6: =SUM(D6:DS6) -> 1150193.4 | D6: 5000 | E6: =D6*1.01 -> 5050 | F6: =E6*1.01 -> 5100.5 | G6: =F6*1.01 -> 5151.505 | H6: =G6*1.01 -> 5203.0201 | I6: =H6*1.01 -> 5255.0503 | J6: =I6*1.01 -> 5307.6008 | K6: =J6*1.01 -> 5360.6768 | L6: =K6*1.01 -> 5414.2835 | ... DS6: =DR6*1.01 -> 16338.549
A7: Выручка | B7: руб. | C7: =SUM(D7:DS7) -> 2.2335408e+13 | D7: =D5*D6 -> 45381780000 | E7: =E5*E6 -> 46293953778 | F7: =F5*F6 -> 4.7224462e+10 | G7: =G5*G6 -> 4.8173674e+10 | H7: =H5*H6 -> 4.9141965e+10 | I7: =I5*I6 -> 5.0129718e+10 | J7: =J5*J6 -> 5.1137326e+10 | K7: =K5*K6 -> 5.2165186e+10 | ... DS7: =DS5*DS6 -> 4.8458335e+11
A8: Инфляция | B8: % | C8: ='Исходные данные'!E40 -> 0.145 | D8: ='Исходные данные'!F40 -> 1.0113476 | E8: ='Исходные данные'!G40 -> 1.022824 | F8: ='Исходные данные'!H40 -> 1.0344306 | G8: ='Исходные данные'!I40 -> 1.046169 | H8: ='Исходные данные'!J40 -> 1.0580405 | I8: ='Исходные данные'!K40 -> 1.0700467 | J8: ='Исходные данные'!L40 -> 1.0821892 | ... DS8: ='Исходные данные'!DU40 -> 3.8730657
A9: Выручка с учетом инфляции | B9: руб. | C9: =SUM(D9:DS9) -> 8.2014455e+13 | D9: =D7+D7*D8 -> 9.1278535e+10 | E9: =E7+E7*E8 -> 9.3644521e+10 | F9: =F7+F7*F8 -> 9.6074892e+10 | G9: =G7+G7*G8 -> 9.8571476e+10 | H9: =H7+H7*H8 -> 1.0113615e+11 | I9: =I7+I7*I8 -> 1.0377086e+11 | J9: =J7+J7*J8 -> 1.0647759e+11 | K9: =K7+K7*K8 -> 1.0925839e+11 | ... DS9: =DS7+DS7*DS8 -> 2.3614065e+12

Sheet Экономический эффект
B2: Выручка
E3: 1 год | Q3: 2 год | AC3: 3 год | AO3: 4 год | BA3: 5 год | BM3: 6 год | BY3: 7 год | CK3: 8 год | CW3: 9 год | DI3: 10 год
B4: Показатель | C4: Ед. из. | D4: Сумма | E4: 1 | F4: 2 | G4: 3 | H4: 4 | I4: 5 | J4: 6 | K4: 7 | L4: 8 | M4: 9 | N4: 10 | O4: 11 | P4: 12 | Q4: 1 | R4: 2 | S4: 3 | T4: 4 | U4: 5 | V4: 6 | W4: 7 | X4: 8 | Y4: 9 | Z4: 10 | AA4: 11 | AB4: 12 | AC4: 1 | AD4: 2 | AE4: 3 | AF4: 4 | AG4: 5 | AH4: 6 | AI4: 7 | AJ4: 8 | AK4: 9 | AL4: 10 | AM4: 11 | AN4: 12 | AO4: 1 | AP4: 2 | AQ4: 3 | AR4: 4 | AS4: 5 | AT4: 6 | AU4: 7 | AV4: 8 | AW4: 9 | AX4: 10 | AY4: 11 | AZ4: 12 | BA4: 1 | BB4: 2 | BC4: 3 | BD4: 4 | BE4: 5 | BF4: 6 | BG4: 7 | BH4: 8 | BI4: 9 | BJ4: 10 | BK4: 11 | BL4: 12 | BM4: 1 | BN4: 2 | BO4: 3 | BP4: 4 | BQ4: 5 | BR4: 6 | BS4: 7 | BT4: 8 | BU4: 9 | BV4: 10 | BW4: 11 | BX4: 12 | BY4: 1 | BZ4: 2 | CA4: 3 | CB4: 4 | CC4: 5 | CD4: 6 | CE4: 7 | CF4: 8 | CG4: 9 | CH4: 10 | CI4: 11 | CJ4: 12 | CK4: 1 | CL4: 2 | CM4: 3 | CN4: 4 | CO4: 5 | CP4: 6 | CQ4: 7 | CR4: 8 | CS4: 9 | CT4: 10 | CU4: 11 | CV4: 12 | CW4: 1 | CX4: 2 | CY4: 3 | CZ4: 4 | DA4: 5 | DB4: 6 | DC4: 7 | DD4: 8 | DE4: 9 | DF4: 10 | DG4: 11 | DH4: 12 | DI4: 1 | DJ4: 2 | DK4: 3 | DL4: 4 | DM4: 5 | DN4: 6 | DO4: 7 | DP4: 8 | DQ4: 9 | DR4: 10 | DS4: 11 | DT4: 12
E5: 1 | F5: 2 | G5: 3 | H5: 4 | I5: 5 | J5: 6 | K5: 7 | L5: 8 | M5: 9 | N5: 10 | O5: 11 | P5: 12 | Q5: 13 | R5: 14 | S5: 15 | T5: 16 | U5: 17 | V5: 18 | W5: 19 | X5: 20 | Y5: 21 | Z5: 22 | AA5: 23 | AB5: 24 | AC5: 25 | AD5: 26 | AE5: 27 | AF5: 28 | AG5: 29 | AH5: 30 | AI5: 31 | AJ5: 32 | AK5: 33 | AL5: 34 | AM5: 35 | AN5: 36 | AO5: 1 | AP5: 2 | AQ5: 3 | AR5: 4 | AS5: 5 | AT5: 6 | AU5: 7 | AV5: 8 | AW5: 9 | AX5: 10 | AY5: 11 | AZ5: 12 | BA5: 13 | BB5: 14 | BC5: 15 | BD5: 16 | BE5: 17 | BF5: 18 | BG5: 19 | BH5: 20 | BI5: 21 | BJ5: 22 | BK5: 23 | BL5: 24 | BM5: 1 | BN5: 2 | BO5: 3 | BP5: 4 | BQ5: 5 | BR5: 6 | BS5: 7 | BT5: 8 | BU5: 9 | BV5: 10 | BW5: 11 | BX5: 12 | BY5: 13 | BZ5: 14 | CA5: 15 | CB5: 16 | CC5: 17 | CD5: 18 | CE5: 19 | CF5: 20 | CG5: 21 | CH5: 22 | CI5: 23 | CJ5: 24 | CK5: 25 | CL5: 26 | CM5: 27 | CN5: 28 | CO5: 29 | CP5: 30 | CQ5: 31 | CR5: 32 | CS5: 33 | CT5: 34 | CU5: 35 | CV5: 36 | CW5: 1 | CX5: 2 | CY5: 3 | CZ5: 4 | DA5: 5 | DB5: 6 | DC5: 7 | DD5: 8 | DE5: 9 | DF5: 10 | DG5: 11 | DH5: 12 | DI5: 13 | DJ5: 14 | DK5: 15 | DL5: 16 | DM5: 17 | DN5: 18 | DO5: 19 | DP5: 20 | DQ5: 21 | DR5: 22 | DS5: 23 | DT5: 24
B6: Экономичесский эффект от роста выручки | D6: =D7 -> 1.1718224e+10 | E6: =E7 -> 0 | F6: =F7 -> 0 | G6: =G7 -> 0 | H6: =H7 -> 0 | I6: =I7 -> 0 | J6: =J7 -> 0 | K6: =K7 -> 0 | ... DT6: =DT7 -> 1.7617054e+08
B7: Экономический эффект: повышение производительности | C7: чел. | D7: =SUM(E7:DT7) -> 1.1718224e+10 | E7: 0 | F7: 0 | G7: 0 | H7: 0 | I7: 0 | J7: 0 | K7: 0 | L7: 0 | M7: 0 | N7: 0 | O7: 0 | P7: 0 | Q7: 60750000 | R7: =Q7*1.01 -> 61357500 | S7: =R7*1.01 -> 61971075 | T7: =S7*1.01 -> 62590786 | U7: =T7*1.01 -> 63216694 | V7: =U7*1.01 -> 63848861 | W7: =V7*1.01 -> 64487349 | X7: =W7*1.01 -> 65132223 | Y7: =X7*1.01 -> 65783545 | ... DT7: =DS7*1.01 -> 1.7617054e+08
B8: Экономический эффект от снижения затрат | C8: руб. | D8: =SUM(D9,D12) -> 9.2588438e+09 | E8: =SUM(E9,E12) -> 0 | F8: =SUM(F9,F12) -> 0 | G8: =SUM(G9,G12) -> 0 | H8: =SUM(H9,H12) -> 0 | I8: =SUM(I9,I12) -> 0 | J8: =SUM(J9,J12) -> 0 | K8: =SUM(K9,K12) -> 0 | ... DT8: =SUM(DT9,DT12) -> 1.3919647e+08
B9: Снижение текучести на 1 п.п.: | C9: руб. | D9: =SUM(E9:DT9) -> 1.5913638e+09 | E9: 0 | F9: =E9*1.01 -> 0 | G9: =F9*1.01 -> 0 | H9: =G9*1.01 -> 0 | I9: =H9*1.01 -> 0 | J9: =I9*1.01 -> 0 | K9: =J9*1.01 -> 0 | L9: =K9*1.01 -> 0 | M9: =L9*1.01 -> 0 | ... P9: =O9*1.01 -> 0 | Q9: 8250000 | R9: =Q9*1.01 -> 8332500 | S9: =R9*1.01 -> 8415825 | T9: =S9*1.01 -> 8499983.2 | U9: =T9*1.01 -> 8584983.1 | V9: =U9*1.01 -> 8670832.9 | W9: =V9*1.01 -> 8757541.2 | X9: =W9*1.01 -> 8845116.7 | Y9: =X9*1.01 -> 8933567.8 | ... DT9: =DS9*1.01 -> 23924394
B10: Затраты на подбор и обучение персонала до | C10: руб. | D10: =SUM(E10:DT10) -> 9720000000 | E10: 0 | F10: 0 | G10: 0 | H10: 0 | I10: 0 | J10: 0 | K10: 0 | L10: 0 | M10: 0 | N10: 0 | O10: 0 | P10: 0 | Q10: 90000000 | R10: 90000000 | S10: 90000000 | T10: 90000000 | U10: 90000000 | V10: 90000000 | W10: 90000000 | X10: 90000000 | Y10: 90000000 | Z10: 90000000 | AA10: 90000000 | AB10: 90000000 | AC10: 90000000 | AD10: 90000000 | AE10: 90000000 | AF10: 90000000 | AG10: 90000000 | AH10: 90000000 | AI10: 90000000 | AJ10: 90000000 | AK10: 90000000 | AL10: 90000000 | AM10: 90000000 | AN10: 90000000 | AO10: 90000000 | AP10: 90000000 | AQ10: 90000000 | AR10: 90000000 | AS10: 90000000 | AT10: 90000000 | AU10: 90000000 | AV10: 90000000 | AW10: 90000000 | AX10: 90000000 | AY10: 90000000 | AZ10: 90000000 | BA10: 90000000 | BB10: 90000000 | BC10: 90000000 | BD10: 90000000 | BE10: 90000000 | BF10: 90000000 | BG10: 90000000 | BH10: 90000000 | BI10: 90000000 | BJ10: 90000000 | BK10: 90000000 | BL10: 90000000 | BM10: 90000000 | BN10: 90000000 | BO10: 90000000 | BP10: 90000000 | BQ10: 90000000 | BR10: 90000000 | BS10: 90000000 | BT10: 90000000 | BU10: 90000000 | BV10: 90000000 | BW10: 90000000 | BX10: 90000000 | BY10: 90000000 | BZ10: 90000000 | CA10: 90000000 | CB10: 90000000 | CC10: 90000000 | CD10: 90000000 | CE10: 90000000 | CF10: 90000000 | CG10: 90000000 | CH10: 90000000 | CI10: 90000000 | CJ10: 90000000 | CK10: 90000000 | CL10: 90000000 | CM10: 90000000 | CN10: 90000000 | CO10: 90000000 | CP10: 90000000 | CQ10: 90000000 | CR10: 90000000 | CS10: 90000000 | CT10: 90000000 | CU10: 90000000 | CV10: 90000000 | CW10: 90000000 | CX10: 90000000 | CY10: 90000000 | CZ10: 90000000 | DA10: 90000000 | DB10: 90000000 | DC10: 90000000 | DD10: 90000000 | DE10: 90000000 | DF10: 90000000 | DG10: 90000000 | DH10: 90000000 | DI10: 90000000 | DJ10: 90000000 | DK10: 90000000 | DL10: 90000000 | DM10: 90000000 | DN10: 90000000 | DO10: 90000000 | DP10: 90000000 | DQ10: 90000000 | DR10: 90000000 | DS10: 90000000 | DT10: 90000000
B11: Затраты на подбор и обучение персонала после | C11: руб. | D11: =SUM(E11:DT11) -> 8.1286362e+09 | E11: 0 | F11: 0 | G11: 0 | H11: 0 | I11: 0 | J11: 0 | K11: 0 | L11: 0 | M11: 0 | N11: 0 | O11: 0 | P11: 0 | Q11: =Q10-Q9 -> 81750000 | R11: =R10-R9 -> 81667500 | S11: =S10-S9 -> 81584175 | T11: =T10-T9 -> 81500017 | U11: =U10-U9 -> 81415017 | V11: =V10-V9 -> 81329167 | W11: =W10-W9 -> 81242459 | X11: =X10-X9 -> 81154883 | ... DT11: =DT10-DT9 -> 66075606
B12: Оптимизация адаптации и подбора персонала, после | C12: руб. | D12: =SUM(E12:DT12) -> 7.66748e+09 | E12: 0 | F12: 0 | G12: 0 | H12: 0 | I12: 0 | J12: 0 | K12: 0 | L12: 0 | M12: 0 | N12: 0 | O12: 0 | P12: 0 | Q12: 39750000 | R12: =Q12*1.01 -> 40147500 | S12: =R12*1.01 -> 40548975 | T12: =S12*1.01 -> 40954465 | U12: =T12*1.01 -> 41364009 | V12: =U12*1.01 -> 41777649 | W12: =V12*1.01 -> 42195426 | X12: =W12*1.01 -> 42617380 | Y12: =X12*1.01 -> 43043554 | ... DT12: =DS12*1.01 -> 1.1527208e+08
B13: Общий экономический эффект | C13: руб. | D13: =SUM(E13:DT13) -> 2.0977068e+10 | E13: =SUM(E7:E12) -> 0 | F13: =SUM(F7:F12) -> 0 | G13: =SUM(G7:G12) -> 0 | H13: =SUM(H7:H12) -> 0 | I13: =SUM(I7:I12) -> 0 | J13: =SUM(J7:J12) -> 0 | K13: =SUM(K7:K12) -> 0 | L13: =SUM(L7:L12) -> 0 | ... P13: =SUM(P7:P12) -> 0 | Q13: =SUM(Q7+Q9+Q12) -> 108750000 | R13: =SUM(R7+R9+R12) -> 109837500 | S13: =SUM(S7+S9+S12) -> 110935875 | T13: =SUM(T7+T9+T12) -> 1.1204523e+08 | U13: =SUM(U7+U9+U12) -> 1.1316569e+08 | V13: =SUM(V7+V9+V12) -> 1.1429734e+08 | W13: =SUM(W7+W9+W12) -> 1.1544032e+08 | X13: =SUM(X7+X9+X12) -> 1.1659472e+08 | ... DT13: =SUM(DT7+DT9+DT12) -> 3.1536701e+08
B14: Коэффициент инфляции | C14: % | D14: ='Исходные данные'!E40 -> 0.145 | E14: ='Исходные данные'!F40 -> 1.0113476 | F14: ='Исходные данные'!G40 -> 1.022824 | G14: ='Исходные данные'!H40 -> 1.0344306 | H14: ='Исходные данные'!I40 -> 1.046169 | I14: ='Исходные данные'!J40 -> 1.0580405 | J14: ='Исходные данные'!K40 -> 1.0700467 | K14: ='Исходные данные'!L40 -> 1.0821892 | ... DT14: ='Исходные данные'!DU40 -> 3.8730657
B15: Экономический эффект с учетом инфляции | C15: руб. | D15: =SUM(E15:DT15) -> 7.324461e+10 | E15: =E13*'Исходные данные'!F40 -> 0 | F15: =F13*'Исходные данные'!G40 -> 0 | G15: =G13*'Исходные данные'!H40 -> 0 | H15: =H13*'Исходные данные'!I40 -> 0 | I15: =I13*'Исходные данные'!J40 -> 0 | J15: =J13*'Исходные данные'!K40 -> 0 | K15: =K13*'Исходные данные'!L40 -> 0 | L15: =L13*'Исходные данные'!M40 -> 0 | ... P15: =P13*'Исходные данные'!Q40 -> 0 | Q15: =Q13+Q13*Q14 -> 2.3468174e+08 | R15: =R13+R13*R14 -> 2.3847187e+08 | S15: =S13+S13*S14 -> 2.4233088e+08 | T15: =T13+T13*T14 -> 2.4626012e+08 | U15: =U13+U13*U14 -> 2.5026098e+08 | V15: =V13+V13*V14 -> 2.5433485e+08 | W15: =W13+W13*W14 -> 2.5848318e+08 | X15: =X13+X13*X14 -> 2.6270744e+08 | ... DT15: =DT13+DT13*DT14 -> 1.5368042e+09
B18: Экономический эффект достигается за счет следующих результатов: - растет выручка за счет роста производительности труда; за счет снижение текучести персонала сокращаются расходы на подбор, отбор и адаптацию персонала, увеличивается производительность за счет сохранения преемственности персонала и человеческого капитала; за счет снижения текусти сокращаются расходы на обучение персонала. На рост выручки влияет: увеличение производительности, выскоая квалификация кадров, сокращение простоев. На затраты влияет: текучестсь кадров, снижение человеческого капитала в организации, снижение опыта работы сотрудников в организации, необходимость дообучения и адаптации.

Sheet Капитальные затраты до
A1: Капитальные затраты
D2: 1 год | P2: 2 год | AB2: 3 год | AN2: 4 год | AZ2: 5 год | BL2: 6 год | BX2: 7 год | CJ2: 8 год | CV2: 9 год | DH2: 10 год
A3: Наименование затрат | B3: Ед. из. | C3: Итого: | D3: 1 | E3: 2 | F3: 3 | G3: 4 | H3: 5 | I3: 6 | J3: 7 | K3: 8 | L3: 9 | M3: 10 | N3: 11 | O3: 12 | P3: 1 | Q3: 2 | R3: 3 | S3: 4 | T3: 5 | U3: 6 | V3: 7 | W3: 8 | X3: 9 | Y3: 10 | Z3: 11 | AA3: 12 | AB3: 1 | AC3: 2 | AD3: 3 | AE3: 4 | AF3: 5 | AG3: 6 | AH3: 7 | AI3: 8 | AJ3: 9 | AK3: 10 | AL3: 11 | AM3: 12 | AN3: 1 | AO3: 2 | AP3: 3 | AQ3: 4 | AR3: 5 | AS3: 6 | AT3: 7 | AU3: 8 | AV3: 9 | AW3: 10 | AX3: 11 | AY3: 12 | AZ3: 1 | BA3: 2 | BB3: 3 | BC3: 4 | BD3: 5 | BE3: 6 | BF3: 7 | BG3: 8 | BH3: 9 | BI3: 10 | BJ3: 11 | BK3: 12 | BL3: 1 | BM3: 2 | BN3: 3 | BO3: 4 | BP3: 5 | BQ3: 6 | BR3: 7 | BS3: 8 | BT3: 9 | BU3: 10 | BV3: 11 | BW3: 12 | BX3: 1 | BY3: 2 | BZ3: 3 | CA3: 4 | CB3: 5 | CC3: 6 | CD3: 7 | CE3: 8 | CF3: 9 | CG3: 10 | CH3: 11 | CI3: 12 | CJ3: 1 | CK3: 2 | CL3: 3 | CM3: 4 | CN3: 5 | CO3: 6 | CP3: 7 | CQ3: 8 | CR3: 9 | CS3: 10 | CT3: 11 | CU3: 12 | CV3: 1 | CW3: 2 | CX3: 3 | CY3: 4 | CZ3: 5 | DA3: 6 | DB3: 7 | DC3: 8 | DD3: 9 | DE3: 10 | DF3: 11 | DG3: 12 | DH3: 1 | DI3: 2 | DJ3: 3 | DK3: 4 | DL3: 5 | DM3: 6 | DN3: 7 | DO3: 8 | DP3: 9 | DQ3: 10 | DR3: 11 | DS3: 12
D4: 1 | E4: 2 | F4: 3 | G4: 4 | H4: 5 | I4: 6 | J4: 7 | K4: 8 | L4: 9 | M4: 10 | N4: 11 | O4: 12 | P4: 13 | Q4: 14 | R4: 15 | S4: 16 | T4: 17 | U4: 18 | V4: 19 | W4: 20 | X4: 21 | Y4: 22 | Z4: 23 | AA4: 24 | AB4: 25 | AC4: 26 | AD4: 27 | AE4: 28 | AF4: 29 | AG4: 30 | AH4: 31 | AI4: 32 | AJ4: 33 | AK4: 34 | AL4: 35 | AM4: 36 | AN4: 1 | AO4: 2 | AP4: 3 | AQ4: 4 | AR4: 5 | AS4: 6 | AT4: 7 | AU4: 8 | AV4: 9 | AW4: 10 | AX4: 11 | AY4: 12 | AZ4: 13 | BA4: 14 | BB4: 15 | BC4: 16 | BD4: 17 | BE4: 18 | BF4: 19 | BG4: 20 | BH4: 21 | BI4: 22 | BJ4: 23 | BK4: 24 | BL4: 1 | BM4: 2 | BN4: 3 | BO4: 4 | BP4: 5 | BQ4: 6 | BR4: 7 | BS4: 8 | BT4: 9 | BU4: 10 | BV4: 11 | BW4: 12 | BX4: 13 | BY4: 14 | BZ4: 15 | CA4: 16 | CB4: 17 | CC4: 18 | CD4: 19 | CE4: 20 | CF4: 21 | CG4: 22 | CH4: 23 | CI4: 24 | CJ4: 25 | CK4: 26 | CL4: 27 | CM4: 28 | CN4: 29 | CO4: 30 | CP4: 31 | CQ4: 32 | CR4: 33 | CS4: 34 | CT4: 35 | CU4: 36 | CV4: 1 | CW4: 2 | CX4: 3 | CY4: 4 | CZ4: 5 | DA4: 6 | DB4: 7 | DC4: 8 | DD4: 9 | DE4: 10 | DF4: 11 | DG4: 12 | DH4: 13 | DI4: 14 | DJ4: 15 | DK4: 16 | DL4: 17 | DM4: 18 | DN4: 19 | DO4: 20 | DP4: 21 | DQ4: 22 | DR4: 23 | DS4: 24
A5: Предпроектное обследование и проектирование решения | B5: руб. | C5: =SUM(D5:DS5) -> 0 | D5: 0 | E5: 0 | F5: 0 | G5: 0 | H5: 0 | I5: 0 | J5: 0 | K5: 0 | L5: 0 | M5: 0 | N5: 0 | O5: 0 | P5: 0 | Q5: 0 | R5: 0 | S5: 0 | T5: 0 | U5: 0 | V5: 0 | W5: 0 | X5: 0 | Y5: 0 | Z5: 0 | AA5: 0 | AB5: 0 | AC5: 0 | AD5: 0 | AE5: 0 | AF5: 0 | AG5: 0 | AH5: 0 | AI5: 0 | AJ5: 0 | AK5: 0 | AL5: 0 | AM5: 0 | AN5: 0 | AO5: 0 | AP5: 0 | AQ5: 0 | AR5: 0 | AS5: 0 | AT5: 0 | AU5: 0 | AV5: 0 | AW5: 0 | AX5: 0 | AY5: 0 | AZ5: 0 | BA5: 0 | BB5: 0 | BC5: 0 | BD5: 0 | BE5: 0 | BF5: 0 | BG5: 0 | BH5: 0 | BI5: 0 | BJ5: 0 | BK5: 0 | BL5: 0 | BM5: 0 | BN5: 0 | BO5: 0 | BP5: 0 | BQ5: 0 | BR5: 0 | BS5: 0 | BT5: 0 | BU5: 0 | BV5: 0 | BW5: 0 | BX5: 0 | BY5: 0 | BZ5: 0 | CA5: 0 | CB5: 0 | CC5: 0 | CD5: 0 | CE5: 0 | CF5: 0 | CG5: 0 | CH5: 0 | CI5: 0 | CJ5: 0 | CK5: 0 | CL5: 0 | CM5: 0 | CN5: 0 | CO5: 0 | CP5: 0 | CQ5: 0 | CR5: 0 | CS5: 0 | CT5: 0 | CU5: 0 | CV5: 0 | CW5: 0 | CX5: 0 | CY5: 0 | CZ5: 0 | DA5: 0 | DB5: 0 | DC5: 0 | DD5: 0 | DE5: 0 | DF5: 0 | DG5: 0 | DH5: 0 | DI5: 0 | DJ5: 0 | DK5: 0 | DL5: 0 | DM5: 0 | DN5: 0 | DO5: 0 | DP5: 0 | DQ5: 0 | DR5: 0 | DS5: 0
A6: Разработка ядра HRM-модуля и всех модулей анализа/рекомендаций/карьеры/витрины/ETL/интеграций/ИБ/тестирования/пилота/документации/обучения/внедрения в эксплуатацию | B6: руб. | C6: =SUM(D6:DS6) -> 0 | D6: 0 | E6: 0 | F6: 0 | G6: 0 | H6: 0 | I6: 0 | J6: 0 | K6: 0 | L6: 0 | M6: 0 | N6: 0 | O6: 0 | P6: 0 | Q6: 0 | R6: 0 | S6: 0 | T6: 0 | U6: 0 | V6: 0 | W6: 0 | X6: 0 | Y6: 0 | Z6: 0 | AA6: 0 | AB6: 0 | AC6: 0 | AD6: 0 | AE6: 0 | AF6: 0 | AG6: 0 | AH6: 0 | AI6: 0 | AJ6: 0 | AK6: 0 | AL6: 0 | AM6: 0 | AN6: 0 | AO6: 0 | AP6: 0 | AQ6: 0 | AR6: 0 | AS6: 0 | AT6: 0 | AU6: 0 | AV6: 0 | AW6: 0 | AX6: 0 | AY6: 0 | AZ6: 0 | BA6: 0 | BB6: 0 | BC6: 0 | BD6: 0 | BE6: 0 | BF6: 0 | BG6: 0 | BH6: 0 | BI6: 0 | BJ6: 0 | BK6: 0 | BL6: 0 | BM6: 0 | BN6: 0 | BO6: 0 | BP6: 0 | BQ6: 0 | BR6: 0 | BS6: 0 | BT6: 0 | BU6: 0 | BV6: 0 | BW6: 0 | BX6: 0 | BY6: 0 | BZ6: 0 | CA6: 0 | CB6: 0 | CC6: 0 | CD6: 0 | CE6: 0 | CF6: 0 | CG6: 0 | CH6: 0 | CI6: 0 | CJ6: 0 | CK6: 0 | CL6: 0 | CM6: 0 | CN6: 0 | CO6: 0 | CP6: 0 | CQ6: 0 | CR6: 0 | CS6: 0 | CT6: 0 | CU6: 0 | CV6: 0 | CW6: 0 | CX6: 0 | CY6: 0 | CZ6: 0 | DA6: 0 | DB6: 0 | DC6: 0 | DD6: 0 | DE6: 0 | DF6: 0 | DG6: 0 | DH6: 0 | DI6: 0 | DJ6: 0 | DK6: 0 | DL6: 0 | DM6: 0 | DN6: 0 | DO6: 0 | DP6: 0 | DQ6: 0 | DR6: 0 | DS6: 0
A7: Приобретение оборудования (серверы, СХД, сеть, рабочие станции, ИБ, резервирование и т.д.) — см. ниже таблицы оборудования | B7: руб. | C7: =SUM(D7:DS7) -> 0 | D7: 0 | E7: 0 | F7: 0 | G7: 0 | H7: 0 | I7: 0 | J7: 0 | K7: 0 | L7: 0 | M7: 0 | N7: 0 | O7: 0 | P7: 0 | Q7: 0 | R7: 0 | S7: 0 | T7: 0 | U7: 0 | V7: 0 | W7: 0 | X7: 0 | Y7: 0 | Z7: 0 | AA7: 0 | AB7: 0 | AC7: 0 | AD7: 0 | AE7: 0 | AF7: 0 | AG7: 0 | AH7: 0 | AI7: 0 | AJ7: 0 | AK7: 0 | AL7: 0 | AM7: 0 | AN7: 0 | AO7: 0 | AP7: 0 | AQ7: 0 | AR7: 0 | AS7: 0 | AT7: 0 | AU7: 0 | AV7: 0 | AW7: 0 | AX7: 0 | AY7: 0 | AZ7: 0 | BA7: 0 | BB7: 0 | BC7: 0 | BD7: 0 | BE7: 0 | BF7: 0 | BG7: 0 | BH7: 0 | BI7: 0 | BJ7: 0 | BK7: 0 | BL7: 0 | BM7: 0 | BN7: 0 | BO7: 0 | BP7: 0 | BQ7: 0 | BR7: 0 | BS7: 0 | BT7: 0 | BU7: 0 | BV7: 0 | BW7: 0 | BX7: 0 | BY7: 0 | BZ7: 0 | CA7: 0 | CB7: 0 | CC7: 0 | CD7: 0 | CE7: 0 | CF7: 0 | CG7: 0 | CH7: 0 | CI7: 0 | CJ7: 0 | CK7: 0 | CL7: 0 | CM7: 0 | CN7: 0 | CO7: 0 | CP7: 0 | CQ7: 0 | CR7: 0 | CS7: 0 | CT7: 0 | CU7: 0 | CV7: 0 | CW7: 0 | CX7: 0 | CY7: 0 | CZ7: 0 | DA7: 0 | DB7: 0 | DC7: 0 | DD7: 0 | DE7: 0 | DF7: 0 | DG7: 0 | DH7: 0 | DI7: 0 | DJ7: 0 | DK7: 0 | DL7: 0 | DM7: 0 | DN7: 0 | DO7: 0 | DP7: 0 | DQ7: 0 | DR7: 0 | DS7: 0
A8: Итого: | C8: =SUM(C5:C7) -> 0 | D8: =SUM(D5:D7) -> 0 | E8: =SUM(E5:E7) -> 0 | F8: =SUM(F5:F7) -> 0 | G8: =SUM(G5:G7) -> 0 | H8: =SUM(H5:H7) -> 0 | I8: =SUM(I5:I7) -> 0 | J8: =SUM(J5:J7) -> 0 | ... DS8: =SUM(DS5:DS7) -> 0
A9: Серверы вычислительного контура для ML/NLP-моделей (GPU/CPU) | B9: руб. | C9: 43000000 | D9: 0 | E9: 0 | F9: 0 | G9: 0 | H9: 0 | I9: 0 | J9: 0 | K9: 0 | L9: 0 | M9: 0 | N9: 0 | O9: 0 | P9: 0 | Q9: 0 | R9: 0 | S9: 0 | T9: 0 | U9: 0 | V9: 0 | W9: 0 | X9: 0 | Y9: 0 | Z9: 0 | AA9: 0 | AB9: 0 | AC9: 0 | AD9: 0 | AE9: 0 | AF9: 0 | AG9: 0 | AH9: 0 | AI9: 0 | AJ9: 0 | AK9: 0 | AL9: 0 | AM9: 0 | AN9: 0 | AO9: 0 | AP9: 0 | AQ9: 0 | AR9: 0 | AS9: 0 | AT9: 0 | AU9: 0 | AV9: 0 | AW9: 0 | AX9: 0 | AY9: 0 | AZ9: 0 | BA9: 0 | BB9: 0 | BC9: 0 | BD9: 0 | BE9: 0 | BF9: 0 | BG9: 0 | BH9: 0 | BI9: 0 | BJ9: 0 | BK9: 0 | BL9: 0 | BM9: 0 | BN9: 0 | BO9: 0 | BP9: 0 | BQ9: 0 | BR9: 0 | BS9: 0 | BT9: 0 | BU9: 0 | BV9: 0 | BW9: 0 | BX9: 0 | BY9: 0 | BZ9: 0 | CA9: 0 | CB9: 0 | CC9: 0 | CD9: 0 | CE9: 0 | CF9: 0 | CG9: 0 | CH9: 0 | CI9: 0 | CJ9: 0 | CK9: 0 | CL9: 0 | CM9: 0 | CN9: 0 | CO9: 0 | CP9: 0 | CQ9: 0 | CR9: 0 | CS9: 0 | CT9: 0 | CU9: 0 | CV9: 0 | CW9: 0 | CX9: 0 | CY9: 0 | CZ9: 0 | DA9: 0 | DB9: 0 | DC9: 0 | DD9: 0 | DE9: 0 | DF9: 0 | DG9: 0 | DH9: 0 | DI9: 0 | DJ9: 0 | DK9: 0 | DL9: 0 | DM9: 0 | DN9: 0 | DO9: 0 | DP9: 0 | DQ9: 0 | DR9: 0 | DS9: 0
A10: Серверы тестового и промышленного контуров (CPU) | B10: руб. | C10: 3000000 | D10: 0 | E10: 0 | F10: 0 | G10: 0 | H10: 0 | I10: 0 | J10: 0 | K10: 0 | L10: 0 | M10: 0 | N10: 0 | O10: 0 | P10: 0 | Q10: 0 | R10: 0 | S10: 0 | T10: 0 | U10: 0 | V10: 0 | W10: 0 | X10: 0 | Y10: 0 | Z10: 0 | AA10: 0 | AB10: 0 | AC10: 0 | AD10: 0 | AE10: 0 | AF10: 0 | AG10: 0 | AH10: 0 | AI10: 0 | AJ10: 0 | AK10: 0 | AL10: 0 | AM10: 0 | AN10: 0 | AO10: 0 | AP10: 0 | AQ10: 0 | AR10: 0 | AS10: 0 | AT10: 0 | AU10: 0 | AV10: 0 | AW10: 0 | AX10: 0 | AY10: 0 | AZ10: 0 | BA10: 0 | BB10: 0 | BC10: 0 | BD10: 0 | BE10: 0 | BF10: 0 | BG10: 0 | BH10: 0 | BI10: 0 | BJ10: 0 | BK10: 0 | BL10: 0 | BM10: 0 | BN10: 0 | BO10: 0 | BP10: 0 | BQ10: 0 | BR10: 0 | BS10: 0 | BT10: 0 | BU10: 0 | BV10: 0 | BW10: 0 | BX10: 0 | BY10: 0 | BZ10: 0 | CA10: 0 | CB10: 0 | CC10: 0 | CD10: 0 | CE10: 0 | CF10: 0 | CG10: 0 | CH10: 0 | CI10: 0 | CJ10: 0 | CK10: 0 | CL10: 0 | CM10: 0 | CN10: 0 | CO10: 0 | CP10: 0 | CQ10: 0 | CR10: 0 | CS10: 0 | CT10: 0 | CU10: 0 | CV10: 0 | CW10: 0 | CX10: 0 | CY10: 0 | CZ10: 0 | DA10: 0 | DB10: 0 | DC10: 0 | DD10: 0 | DE10: 0 | DF10: 0 | DG10: 0 | DH10: 0 | DI10: 0 | DJ10: 0 | DK10: 0 | DL10: 0 | DM10: 0 | DN10: 0 | DO10: 0 | DP10: 0 | DQ10: 0 | DR10: 0 | DS10: 0
A11: СХД для исторических данных и моделей (NAS/SAN) | B11: руб. | C11: 6000000 | D11: 0 | E11: 0 | F11: 0 | G11: 0 | H11: 0 | I11: 0 | J11: 0 | K11: 0 | L11: 0 | M11: 0 | N11: 0 | O11: 0 | P11: 0 | Q11: 0 | R11: 0 | S11: 0 | T11: 0 | U11: 0 | V11: 0 | W11: 0 | X11: 0 | Y11: 0 | Z11: 0 | AA11: 0 | AB11: 0 | AC11: 0 | AD11: 0 | AE11: 0 | AF11: 0 | AG11: 0 | AH11: 0 | AI11: 0 | AJ11: 0 | AK11: 0 | AL11: 0 | AM11: 0 | AN11: 0 | AO11: 0 | AP11: 0 | AQ11: 0 | AR11: 0 | AS11: 0 | AT11: 0 | AU11: 0 | AV11: 0 | AW11: 0 | AX11: 0 | AY11: 0 | AZ11: 0 | BA11: 0 | BB11: 0 | BC11: 0 | BD11: 0 | BE11: 0 | BF11: 0 | BG11: 0 | BH11: 0 | BI11: 0 | BJ11: 0 | BK11: 0 | BL11: 0 | BM11: 0 | BN11: 0 | BO11: 0 | BP11: 0 | BQ11: 0 | BR11: 0 | BS11: 0 | BT11: 0 | BU11: 0 | BV11: 0 | BW11: 0 | BX11: 0 | BY11: 0 | BZ11: 0 | CA11: 0 | CB11: 0 | CC11: 0 | CD11: 0 | CE11: 0 | CF11: 0 | CG11: 0 | CH11: 0 | CI11: 0 | CJ11: 0 | CK11: 0 | CL11: 0 | CM11: 0 | CN11: 0 | CO11: 0 | CP11: 0 | CQ11: 0 | CR11: 0 | CS11: 0 | CT11: 0 | CU11: 0 | CV11: 0 | CW11: 0 | CX11: 0 | CY11: 0 | CZ11: 0 | DA11: 0 | DB11: 0 | DC11: 0 | DD11: 0 | DE11: 0 | DF11: 0 | DG11: 0 | DH11: 0 | DI11: 0 | DJ11: 0 | DK11: 0 | DL11: 0 | DM11: 0 | DN11: 0 | DO11: 0 | DP11: 0 | DQ11: 0 | DR11: 0 | DS11: 0
A12: Сетевое оборудование ядра проекта (коммутаторы, маршрутизаторы) | B12: руб. | C12: 2100000 | D12: 0 | E12: 0 | F12: 0 | G12: 0 | H12: 0 | I12: 0 | J12: 0 | K12: 0 | L12: 0 | M12: 0 | N12: 0 | O12: 0 | P12: 0 | Q12: 0 | R12: 0 | S12: 0 | T12: 0 | U12: 0 | V12: 0 | W12: 0 | X12: 0 | Y12: 0 | Z12: 0 | AA12: 0 | AB12: 0 | AC12: 0 | AD12: 0 | AE12: 0 | AF12: 0 | AG12: 0 | AH12: 0 | AI12: 0 | AJ12: 0 | AK12: 0 | AL12: 0 | AM12: 0 | AN12: 0 | AO12: 0 | AP12: 0 | AQ12: 0 | AR12: 0 | AS12: 0 | AT12: 0 | AU12: 0 | AV12: 0 | AW12: 0 | AX12: 0 | AY12: 0 | AZ12: 0 | BA12: 0 | BB12: 0 | BC12: 0 | BD12: 0 | BE12: 0 | BF12: 0 | BG12: 0 | BH12: 0 | BI12: 0 | BJ12: 0 | BK12: 0 | BL12: 0 | BM12: 0 | BN12: 0 | BO12: 0 | BP12: 0 | BQ12: 0 | BR12: 0 | BS12: 0 | BT12: 0 | BU12: 0 | BV12: 0 | BW12: 0 | BX12: 0 | BY12: 0 | BZ12: 0 | CA12: 0 | CB12: 0 | CC12: 0 | CD12: 0 | CE12: 0 | CF12: 0 | CG12: 0 | CH12: 0 | CI12: 0 | CJ12: 0 | CK12: 0 | CL12: 0 | CM12: 0 | CN12: 0 | CO12: 0 | CP12: 0 | CQ12: 0 | CR12: 0 | CS12: 0 | CT12: 0 | CU12: 0 | CV12: 0 | CW12: 0 | CX12: 0 | CY12: 0 | CZ12: 0 | DA12: 0 | DB12: 0 | DC12: 0 | DD12: 0 | DE12: 0 | DF12: 0 | DG12: 0 | DH12: 0 | DI12: 0 | DJ12: 0 | DK12: 0 | DL12: 0 | DM12: 0 | DN12: 0 | DO12: 0 | DP12: 0 | DQ12: 0 | DR12: 0 | DS12: 0
A13: Рабочие станции разработчиков/аналитиков (high-end) | B13: руб. | C13: 3000000 | D13: 0 | E13: 0 | F13: 0 | G13: 0 | H13: 0 | I13: 0 | J13: 0 | K13: 0 | L13: 0 | M13: 0 | N13: 0 | O13: 0 | P13: 0 | Q13: 0 | R13: 0 | S13: 0 | T13: 0 | U13: 0 | V13: 0 | W13: 0 | X13: 0 | Y13: 0 | Z13: 0 | AA13: 0 | AB13: 0 | AC13: 0 | AD13: 0 | AE13: 0 | AF13: 0 | AG13: 0 | AH13: 0 | AI13: 0 | AJ13: 0 | AK13: 0 | AL13: 0 | AM13: 0 | AN13: 0 | AO13: 0 | AP13: 0 | AQ13: 0 | AR13: 0 | AS13: 0 | AT13: 0 | AU13: 0 | AV13: 0 | AW13: 0 | AX13: 0 | AY13: 0 | AZ13: 0 | BA13: 0 | BB13: 0 | BC13: 0 | BD13: 0 | BE13: 0 | BF13: 0 | BG13: 0 | BH13: 0 | BI13: 0 | BJ13: 0 | BK13: 0 | BL13: 0 | BM13: 0 | BN13: 0 | BO13: 0 | BP13: 0 | BQ13: 0 | BR13: 0 | BS13: 0 | BT13: 0 | BU13: 0 | BV13: 0 | BW13: 0 | BX13: 0 | BY13: 0 | BZ13: 0 | CA13: 0 | CB13: 0 | CC13: 0 | CD13: 0 | CE13: 0 | CF13: 0 | CG13: 0 | CH13: 0 | CI13: 0 | CJ13: 0 | CK13: 0 | CL13: 0 | CM13: 0 | CN13: 0 | CO13: 0 | CP13: 0 | CQ13: 0 | CR13: 0 | CS13: 0 | CT13: 0 | CU13: 0 | CV13: 0 | CW13: 0 | CX13: 0 | CY13: 0 | CZ13: 0 | DA13: 0 | DB13: 0 | DC13: 0 | DD13: 0 | DE13: 0 | DF13: 0 | DG13: 0 | DH13: 0 | DI13: 0 | DJ13: 0 | DK13: 0 | DL13: 0 | DM13: 0 | DN13: 0 | DO13: 0 | DP13: 0 | DQ13: 0 | DR13: 0 | DS13: 0
A14: Средства ИБ: межсетевые экраны, DLP, SIEM, HSM и др. | B14: руб. | C14: 2800000 | D14: 0 | E14: 0 | F14: 0 | G14: 0 | H14: 0 | I14: 0 | J14: 0 | K14: 0 | L14: 0 | M14: 0 | N14: 0 | O14: 0 | P14: 0 | Q14: 0 | R14: 0 | S14: 0 | T14: 0 | U14: 0 | V14: 0 | W14: 0 | X14: 0 | Y14: 0 | Z14: 0 | AA14: 0 | AB14: 0 | AC14: 0 | AD14: 0 | AE14: 0 | AF14: 0 | AG14: 0 | AH14: 0 | AI14: 0 | AJ14: 0 | AK14: 0 | AL14: 0 | AM14: 0 | AN14: 0 | AO14: 0 | AP14: 0 | AQ14: 0 | AR14: 0 | AS14: 0 | AT14: 0 | AU14: 0 | AV14: 0 | AW14: 0 | AX14: 0 | AY14: 0 | AZ14: 0 | BA14: 0 | BB14: 0 | BC14: 0 | BD14: 0 | BE14: 0 | BF14: 0 | BG14: 0 | BH14: 0 | BI14: 0 | BJ14: 0 | BK14: 0 | BL14: 0 | BM14: 0 | BN14: 0 | BO14: 0 | BP14: 0 | BQ14: 0 | BR14: 0 | BS14: 0 | BT14: 0 | BU14: 0 | BV14: 0 | BW14: 0 | BX14: 0 | BY14: 0 | BZ14: 0 | CA14: 0 | CB14: 0 | CC14: 0 | CD14: 0 | CE14: 0 | CF14: 0 | CG14: 0 | CH14: 0 | CI14: 0 | CJ14: 0 | CK14: 0 | CL14: 0 | CM14: 0 | CN14: 0 | CO14: 0 | CP14: 0 | CQ14: 0 | CR14: 0 | CS14: 0 | CT14: 0 | CU14: 0 | CV14: 0 | CW14: 0 | CX14: 0 | CY14: 0 | CZ14: 0 | DA14: 0 | DB14: 0 | DC14: 0 | DD14: 0 | DE14: 0 | DF14: 0 | DG14: 0 | DH14: 0 | DI14: 0 | DJ14: 0 | DK14: 0 | DL14: 0 | DM14: 0 | DN14: 0 | DO14: 0 | DP14: 0 | DQ14: 0 | DR14: 0 | DS14: 0
A15: Резервное копирование и отказоустойчивость (СХД+ПО) | B15: руб. | C15: 3600000 | D15: 0 | E15: 0 | F15: 0 | G15: 0 | H15: 0 | I15: 0 | J15: 0 | K15: 0 | L15: 0 | M15: 0 | N15: 0 | O15: 0 | P15: 0 | Q15: 0 | R15: 0 | S15: 0 | T15: 0 | U15: 0 | V15: 0 | W15: 0 | X15: 0 | Y15: 0 | Z15: 0 | AA15: 0 | AB15: 0 | AC15: 0 | AD15: 0 | AE15: 0 | AF15: 0 | AG15: 0 | AH15: 0 | AI15: 0 | AJ15: 0 | AK15: 0 | AL15: 0 | AM15: 0 | AN15: 0 | AO15: 0 | AP15: 0 | AQ15: 0 | AR15: 0 | AS15: 0 | AT15: 0 | AU15: 0 | AV15: 0 | AW15: 0 | AX15: 0 | AY15: 0 | AZ15: 0 | BA15: 0 | BB15: 0 | BC15: 0 | BD15: 0 | BE15: 0 | BF15: 0 | BG15: 0 | BH15: 0 | BI15: 0 | BJ15: 0 | BK15: 0 | BL15: 0 | BM15: 0 | BN15: 0 | BO15: 0 | BP15: 0 | BQ15: 0 | BR15: 0 | BS15: 0 | BT15: 0 | BU15: 0 | BV15: 0 | BW15: 0 | BX15: 0 | BY15: 0 | BZ15: 0 | CA15: 0 | CB15: 0 | CC15: 0 | CD15: 0 | CE15: 0 | CF15: 0 | CG15: 0 | CH15: 0 | CI15: 0 | CJ15: 0 | CK15: 0 | CL15: 0 | CM15: 0 | CN15: 0 | CO15: 0 | CP15: 0 | CQ15: 0 | CR15: 0 | CS15: 0 | CT15: 0 | CU15: 0 | CV15: 0 | CW15: 0 | CX15: 0 | CY15: 0 | CZ15: 0 | DA15: 0 | DB15: 0 | DC15: 0 | DD15: 0 | DE15: 0 | DF15: 0 | DG15: 0 | DH15: 0 | DI15: 0 | DJ15: 0 | DK15: 0 | DL15: 0 | DM15: 0 | DN15: 0 | DO15: 0 | DP15: 0 | DQ15: 0 | DR15: 0 | DS15: 0
